Workbook
Name _Hlk198728842: 委託業務仕様書の作成!$B$67
Name _Hlk198728842: 委託先の情報管理!#REF!
Name ・_貸与品の場合: #REF!
Name ・_貸与品の場合: #REF!
Name ・_貸与品の場合: #REF!
Name ・_貸与品の場合: #REF!
Name ・_貸与品の場合: #REF!
Name ・_貸与品の場合: #REF!
Name ・_貸与品の場合: #REF!
Name ・_貸与品の場合: #REF!
Name ・_貸与品の場合: #REF!
Name ・_貸与品の場合: #REF!
Name ・_貸与品の場合: #REF!
Name ・_貸与品の場合: #REF!
Name ・_貸与品の場合: #REF!
Name ・_貸与品の場合: #REF!
Name ・_貸与品の場合: #REF!
Name kisyamei: 委託先適合性確認票!#REF!
Name OLE_LINK1: '委託計画書（変更書）'!$Q$5
Name OLE_LINK1: 品質計画書!#REF!
Name OLE_LINK4: 契約内容確認書!$AT$83
Name チェック: #REF!
Name チェック: #REF!
Name チェック: #REF!
Name チェック: #REF!
Name チェック: #REF!
Name チェック: #REF!
Name チェック: #REF!
Name チェック: #REF!
Name チェック: #REF!
Name チェック: #REF!
Name チェック: #REF!
Name チェック: #REF!
Name チェック: #REF!
Name チェック: #REF!
Name チェック: #REF!
Name て: #REF!
Name 改善提案処置管理票: #REF!
Name 改善提案処置管理票: #REF!
Name 書式: #REF!
Name 書式: #REF!
Name 書式: #REF!
Name 書式: #REF!
Name 書式: #REF!
Name 書式: #REF!
Name 書式: #REF!
Name 書式: 受注計画書!$A$2:$V$58
Name 書式: #REF!
Name 書式: #REF!
Name 書式: #REF!
Name 是正処置管理票: #REF!
Name 是正処置管理票: #REF!
Name 是正処置管理票: #REF!
Name 目次: #REF!
Name 目次: #REF!
Name 目次: #REF!

Sheet 目次
G1: 参考帳票（2026/1/9）
B2: 社会基盤ユニット 土木本部、ジオフロント本部 『業務品質管理要領（QC1-003）』 参考帳票
B4: 記録名 | C4: No. | D4: 参考帳票名 | E4: リンク | G4: 改訂日 | H4: 改訂内容
B5: 基本データ | E5: =HYPERLINK("#基本データ!A1","●") -> ● | G5: 46031 | H5: 入力欄（チェック体制）の追加
B6: 業務品質管理全体フロー | E6: =HYPERLINK("#フロー!A1","●") -> ● | G6: 46031 | H6: 新規追加
B7: 業務品質文書管理台帳 | C7: 1 | D7: 業務品質文書管理台帳 | E7: =HYPERLINK("#業務品質文書管理台帳!A2","●") -> ● | G7: 46031 | H7: 2024年度土木本部ジオフロント本部内部監査指摘事項の追記
B8: 契約内容確認記録 | C8: 2 | D8: 契約内容確認書 | E8: =HYPERLINK("#契約内容確認書!A2","●") -> ● | G8: 46031 | H8: リスク評価の審議レベルの追加、表現の修正、チェックボックスのプルダウン選択化
C9: 3 | D9: 契約内容確認書（記載例） | E9: =HYPERLINK("#記載例契約内容確認書!A2","●") -> ● | G9: 46031 | H9: リスク評価の審議レベルの追加、表現の修正、チェックボックスのプルダウン選択化
C10: 4 | D10: 契約内容変更確認書 | E10: =HYPERLINK("#契約内容変更確認書!A2","●") -> ● | G10: 46031 | H10: リスク評価の審議レベルの追加、表現の修正、チェックボックスのプルダウン選択化
B11: （参考）リスク評価シート | C11: 5 | D11: （参考）リスク評価シート | E11: =HYPERLINK("#リスク評価シート!A2","●") -> ● | G11: 46031 | H11: 受注業務のリスク管理方法の指針より引用（使用時は最新版を確認すること）
B12: （参考）リスク対策シート | C12: 6 | D12: （参考）リスク対策シート | E12: =HYPERLINK("#リスク対策シート!A2","●") -> ● | G12: 46031 | H12: 受注業務のリスク管理方法の指針より引用（使用時は最新版を確認すること）
C13: 7 | D13: 受注計画書 | E13: =HYPERLINK("#受注計画書!A2","●") -> ● | G13: 46031 | H13: 受注計画承認取扱要領（BB1-008）より引用（使用時は最新版を確認すること）
C14: 8 | D14: 簡易委託受注 ・実行書 | E14: =HYPERLINK("#簡易委託受注・実行書!A2","●") -> ● | G14: 46031 | H14: 新規追加
B15: 委託計画記録 | C15: 9 | D15: 委託計画書/変更書 | E15: =HYPERLINK("#委託計画書変更書!A2","●") -> ● | G15: 46031 | H15: 委託業務運用要領（BC2-001）より引用（使用時は最新版を確認すること）
B16: 品質計画記録 | C16: 10 | D16: 品質計画書 | E16: =HYPERLINK("#品質計画書!A2","●") -> ● | G16: 46031 | H16: リスク評価の審議レベルの追加、表現の修正、チェックボックスのプルダウン選択化
C17: 11 | D17: 品質計画書（記載例） | E17: =HYPERLINK("#【記載例】品質計画書!A2","●") -> ● | G17: 46031 | H17: リスク評価の審議レベルの追加、全体をレビュー
C18: 12 | D18: 特定業務品質計画書 | E18: =HYPERLINK("#特定業務品質計画書!A2","●") -> ● | G18: 46031 | H18: リスク評価の審議レベルの追加、表現の修正、チェックボックスのプルダウン選択化
B19: 顧客所有物記録 | C19: 13 | D19: 顧客所有物確認書 | E19: =HYPERLINK("#顧客所有物確認書!A2","●") -> ● | G19: 46031 | H19: 全体をレビュー
C20: 14 | D20: 安全事前評価議事録 | E20: =HYPERLINK("#安全事前評価議事録!A2","●") -> ● | G20: 46031 | H20: 安全事前評価実施要領（BC1-001）より引用（使用時は最新版を確認すること）
B21: 計測機器記録 | C21: 15 | D21: 計測機器使用記録 | E21: =HYPERLINK("#計測機器使用記録!A2","●") -> ● | G21: 46031 | H21: 表現の修正、チェックボックスのプルダウン選択化
C22: 16 | D22: 計測機器校正記録 | E22: =HYPERLINK("#計測機器校正記録!A2","●") -> ● | G22: 46031 | H22: 全体をレビュー
B23: 原子力業務に係る管理記録 | C23: 17 | D23: 別紙2 出張時持ち出し管理簿 | E23: =HYPERLINK("#別紙２出張時持ち出し管理簿!A2","●") -> ● | G23: 46031 | H23: 全体をレビュー
C24: 18 | D24: 別紙3 原子力情報に関する教育・実績管理表 | E24: =HYPERLINK("#別紙３原子力情報に関する教育・実績管理表!A2","●") -> ● | G24: 46031 | H24: 全体をレビュー
C25: 19 | D25: 別紙6 原子力情報取り扱い管理記録 | E25: =HYPERLINK("#別紙06原子力情報取り扱い管理記録!A2","●") -> ● | G25: 46031 | H25: 全体をレビュー
B26: 設計業務依頼記録・委託関係記録 | C26: 20 | D26: 設計業務依頼票 | E26: =HYPERLINK("#設計業務依頼票!A2","●") -> ● | G26: 46031 | H26: 【全社受注契約業務取扱要領（BB1-001）を参照】（使用時は最新版を確認すること）
C27: 21 | D27: 変更依頼・指示書 | E27: =HYPERLINK("#変更依頼・指示書!A2","●") -> ● | G27: 46031 | H27: 全体をレビュー
B28: 委託関係記録 | C28: 22 | D28: 委託業務仕様書の作成（委託契約要領） | E28: =HYPERLINK("#委託業務仕様書の作成!A2","●") -> ● | G28: 46031 | H28: 全体をレビュー
C29: 23 | D29: 委託先の情報管理（原子力業務以外） | E29: =HYPERLINK("#委託先の情報管理!A2","●") -> ● | G29: 46031 | H29: 全体をレビュー
C30: 24 | D30: 委託先監査に関する仕様書の記載 | E30: =HYPERLINK("#委託先監査に関する仕様書の記載!A2","●") -> ● | G30: 46031 | H30: 全体をレビュー
C31: 25 | D31: 原子力業務における委託先への追加要求事項 | E31: =HYPERLINK("#原子力業務の追加要求事項!A2","●") -> ● | G31: 46031 | H31: 全体をレビュー
C32: 26 | D32: 生成AIに関する仕様書への記載 | E32: =HYPERLINK("#生成AIに関する仕様書への記載!A2","●") -> ● | G32: 46031 | H32: 新規作成
C33: 27 | D33: 委託業務仕様書チェック項目 | E33: =HYPERLINK("#仕様書チェック表!A2","●") -> ● | G33: 46031 | H33: 新規作成
C34: 28 | D34: 別紙4 原子力業務に対する委託先適合性確認票 | E34: =HYPERLINK("#委託先適合性確認票!A2","●") -> ● | G34: 46031 | H34: 全体をレビュー
C35: 29 | D35: 別紙5 委託先品質監査チェックシート | E35: =HYPERLINK("#⑤別紙５委託先品質監査チェックシート!A2","●") -> ● | G35: 46031 | H35: 全体をレビュー
C36: 30 | D36: 委託先への支給品・貸与品確認書 | E36: =HYPERLINK("#支給品・貸与品確認書!A2","●") -> ● | G36: 46031 | H36: 全体をレビュー、表現の修正、チェックボックスのプルダウン選択化
C37: 31 | D37: 借用書、備品・消耗品貸出簿 | E37: =HYPERLINK("#'借用書、備品・消耗品貸出簿'!A2","●") -> ● | G37: 46031 | H37: 新規作成
C38: 32 | D38: 委託成果品検査記録 | E38: =HYPERLINK("#委託成果品検査記録!A2","●") -> ● | G38: 46031 | H38: 表現の修正、チェックボックスのプルダウン選択化
C39: 33 | D39: 委託業務提示資料廃棄証明届出書 | E39: =HYPERLINK("#委託業務提示資料廃棄証明届出書!A2","●") -> ● | G39: 46031 | H39: 新規追加
B40: 設計検査記録・妥当性確認記録 | C40: 34 | D40: 設計検査記録 | E40: =HYPERLINK("#設計検査記録!A2","●") -> ● | G40: 46031 | H40: 表現の修正、チェックボックスのプルダウン選択化
C41: 35 | D41: 工程内検査記録 | E41: =HYPERLINK("#工程内検査記録!A2","●") -> ● | G41: 46031 | H41: 表現の修正、チェックボックスのプルダウン選択化
...

Sheet 基本データ
B2: 共通項目シート | E2: （例） | I2: 目次へ戻る | J2: =HYPERLINK("#目次!A1","●") -> ●
B3: 件名コード | D3: LG***** | E3: LG220** | I3: フロー図へ戻る | J3: =HYPERLINK("#フロー!A1","●") -> ●
B4: 件名 | D4: 〇〇設計業務委託 | E4: 〇〇設計委託
B5: お客さま | D5: 東京電力HD | E5: 東京電力HD
B6: 受託期間(自) | D6: 45017 | E6: 45017
B7: 受託期間(至) | D7: 45382 | E7: 45382 | I7: 改訂履歴
B8: チェック 体制 | C8: 承認者氏名 | D8: 東設 太郎 | I8: 改訂日 | J8: 改訂内容
C9: 審査者氏名 | D9: 東設 次郎 | I9: 46031 | J9: 入力欄（チェック体制）、受注金額の追加
C10: 実施責任者氏名 | D10: 東設 三郎
B11: 受注額 | C11: 単位；円 | D11: 5000000
B12: 上記を入力すると、リンクで各QMS文書に自動入力されます。

Sheet フロー
A1: rev. | B1: 46031
A2: =HYPERLINK("#目次!A2","●目次へ") -> ●目次へ
S43: 請求前
Q45: ※委託G作成資料

Sheet フロー (業務品質管理　全体業務品質文書管理台帳図)

Sheet フロー (（別紙1）本部間 部間依頼フロー図)

Sheet フロー (（別紙2）委託業務フロー図)
E24: 請求前
C26: ※委託G作成資料

Sheet 業務品質文書管理台帳
J1: 参考帳票（2026/1/9） | Q1: 参考帳票（2026/1/9）
B2: 業務品質文書管理台帳
B3: 件名コード | D3: =基本データ!D3 -> LG***** | J3: 凡例 ●：該当 | X3: 目次へ戻る | Y3: =HYPERLINK("#目次!A1","●") -> ●
B4: 件名 | D4: =基本データ!D4 -> 〇〇設計業務委託 | J4: 〇：場合により該当 | X4: フローへ戻る | Y4: =HYPERLINK("#フロー!A2","●") -> ●
J5: ※：品質管理と兼用
B7: 収納番号 | C7: 必要記録 | D7: 確認事項 | F7: 記録となる資料 （太字は参考帳票あり） | J7: 作成する書類 | M7: 受領 (ﾌｧｲﾘﾝｸﾞ) | N7: ﾁｪｯｸ欄 | P7: 確認事項 | R7: ﾁｪｯｸ欄
J8: 品質 管理 | K8: 業務 実施 | L8: 社内 手続 | X8: 改訂履歴
X9: 改訂日 | Y9: 改訂内容
B10: 1 | C10: 契約内容確認記録 | D10: ・ | E10: 顧客要求事項（実施項目，実施数量，その他） | F10: ◆契約内容確認書 | J10: ● | K10: ※ | P10: ・ | Q10: 件名設定時または契約前の情報（金額未定依頼を含む）で，受注予想額が1億円以上見込まれる場合は，受注計画書（積算書添付）作成し，社長まで承認を得ているか？ | X10: 44964 | Y10: 2022年度土木本部ジオフロント本部内部監査指摘事項を追記
G11: ○業務受付処理表 | M11: ● | X11: 45001 | Y11: 確認事項欄で内容が重複するものを整理
G12: ○積算書作成依頼 | M12: ● | P12: ・ | Q12: 受注総額が1億円以上で、かつ複数の部署で受注する場合、主管部が代表して総額で受注計画書の社長承認を得ているか？【2024年度】 | X12: 45009 | Y12: 確認事項欄の順序を見直し | AD12: ③ | AE12: 受注総額が1億円以上で、かつ複数の部署で受注する場合、主管部が代表して総額で受注計画書の社長承認を得ているか？【2024年度】
D13: ・ | E13: 実施能力 | H13: ・ | I13: 見積依頼書 | M13: ● | P13: ・ | Q13: 見積額が3000万円以上の場合、本部長の承認を得ているか？ | X13: 45043 | Y13: 2022年度内部監査指摘事項に対する対応
D14: ・ | E14: 受注業務のリスク管理（契約前段階） | H14: ・ | I14: 仕様書 | M14: ● | P14: ・ | Q14: 「受注計画書」の作成・承認に関する詳細は，TEPSCO掲示板「規程・要領集」の受注計画・実行承認取扱要領（BT1-010）を参照とする。 | X14: 45099 | Y14: 誤字の修正（規定→規程、実行書→実行承認） | AE14: 「受注計画書」の作成・承認に関する詳細は，TEPSCO掲示板「規程・要領集」の受注計画・実行承認取扱要領（BT1-010）を参照とする。
H15: ・ | I15: 設計書 | M15: ● | P15: ・ | Q15: お客さまの仕様書に記載がなくとも社会的要求事項である必要不可欠な関連法令・規制などは契約内容確認時に、お客さまに確認し、契約内容確認書に記載しているか？ | X15: 45309 | Y15: 2023年度再エネ本部内部監査指摘事項の追記 | AD15: ② | AE15: お客さまの仕様書に記載がなくとも社会的要求事項である必要不可欠な関連法令・規制などは契約内容確認時に、お客さまに確認し、契約内容確認書に記載しているか？
G16: 〇リスク対策シート | L16: 〇 | X16: 45768 | Y16: 2024年度土木本部ジオフロント本部内部監査指摘事項の追記
G17: 〇積算書 | L17: ● | P17: ・ | Q17: 当該業務に関するお客さまの諸規定の内容を確認し、当該業務に適用する必要がある場合には、その名称を品質計画書に記載しているか？ | X17: 46031 | Y17: 全体をレビュー | AD17: ① | AE17: 当該業務に関するお客さまの諸規定の内容を確認し、当該業務に適用する必要がある場合には、その名称を品質計画書に記載しているか？
G18: 〇提示額応答記録 | M18: ● | P18: ・ | Q18: 契約内容の確認者は業務の経験・実績、技術力のある技術者を選任しているか？ | AD18: ① | AE18: 契約内容の確認者は業務の経験・実績、技術力のある技術者を選任しているか？
G19: 〇受注情報（契約書，請書等） | M19: ● | P19: ・ | Q19: 契約内容確認では、事前にお客さまとのやり取りがある場合は、その記録を契約内容確認と紐づけをしているか？【2024年度】 | AD19: ② | AE19: 契約内容確認では、事前にお客さまとのやり取りがある場合は、その記録を契約内容確認と紐づけをしているか？【2024年度】
G20: 〇議事録類 | K20: ● | P20: ・ | Q20: 契約内容確認記録、品質計画書、検査記録等とその内容を補完する別資料とを確実に紐づけしているか？ | AD20: ② | AE20: 契約内容確認記録、品質計画書、検査記録等とその内容を補完する別資料とを確実に紐づけしているか？
D21: （他本部より依頼される場合） | G21: 〇設計業務依頼票 | M21: ● | P21: ・ | Q21: 各種帳票の日付は記載されているか、それぞれの整合性はとれているか？。 | AD21: ⑤ | AE21: 各種帳票の日付は記載されているか、それぞれの整合性はとれているか？。
D22: （東電Gの簡易委託の場合） | G22: 〇簡易委託受注・委託発注実行書 | L22: ●
C24: 契約内容変更記録 | F24: ◆ | G24: 契約内容変更確認書 | J24: ● | K24: ※ | P24: ・ | Q24: 契約変更に係る事項は議事録を作成しているか？。
G25: ○ | H25: 顧客よりの変更指示書類 | M25: ● | P25: ・ | Q25: 契約内容の変更では、「契約内容確認書」ではなく、「契約内容変更確認書」にて対応しているか？
H26: ・ | I26: 変更指示書 | M26: ● | P26: ・ | Q26: 設計内容に変更が生じた場合、実施責任者は変更により発生するリスクの有無・内容・影響について主管部長と協議し、それを記録し、管理しているか？
H27: ・ | I27: 変更仕様書 | M27: ●
H28: ・ | I28: 変更設計書 | M28: ● | P28: ・ | Q28: 「契約内容変更確認書」において、契約内容変更の経緯が分かるようエビデンスを記録に残しているか？【2024年度】
G29: 〇 | H29: 変更依頼・指示書 | L29: ●
G30: 〇 | H30: 議事録類 | K30: ●
B32: 2 | C32: 品質計画記録 | D32: ・ | E32: 実施項目 | F32: ◆ | G32: 品質計画書 | J32: ● | P32: ・ | Q32: 品質計画書のチェック欄（「有・無」，□）と各項目に記入漏れはないか？。
D33: ・ | E33: 実施体制 | G33: 〇 | H33: 実施計画書 | K33: ● | P33: ・ | Q33: 計画書等に地図・書籍等を転載する場合，出所・出典が記載されているか？。
D34: ・ | E34: 必要不可欠な法令，基準類 | G34: 〇 | H34: 安全計画書 | K34: ● | P34: ・ | Q34: 品質計画書と委託計画書に整合はとれているか？。
D35: ・ | E35: 使用プログラム | H35: ・ | I35: 新規入場者教育記録（安全計画書表紙に対象者の署名） | J35: ● | P35: ・ | Q35: 現場作業の作業員名簿など個人情報（自宅の住所，電話番号等）を持たざるを得ない場合，管理台帳に記載して個人情報管理責任者（個人情報管理担当者）に報告しているか？（個人情報保護要領）
D37: ・ | E37: 業務工程 | H37: ・ | I37: 安全教育記録（安全計画書表紙に対象者の署名） | J37: ● | P37: ・ | Q37: 個人情報を記録した重要な書類等については，実施責任者が施錠保管しているか？
D38: ・ | E38: 受注業務のリスク管理（受注・業務着手段階，業務実施・引渡し段階） | P38: ・ | Q38: 契約内容確認記録、品質計画書、検査記録等とその内容を補完する別資料とを確実に紐づけしているか？
G39: 〇 | H39: リスク対策シート | L39: 〇 | P39: ・ | Q39: 使用するプログラムはバージョンにいたるまで、それを特定できるように明示しているか？
G40: 〇 | H40: 品質保証計画 | K40: ● | P40: ・ | Q40: 委託先がプログラムを使用する場合でも、「プログラムの使用：有」とし、プログラム名を記載しているか？また、プログラムの検証記録を受領しているか？
F41: ◆安全事前評価議事録 | J41: ●
G42: 〇 | H42: 作業員名簿 | K42: ● | P42: ・ | Q42: 設計検査，妥当性確認などの計画されたイベントについては，それぞれ重要なポイントであることから，最後まで，適宜，手書き等にて加筆し，記録されているか？【2024年度】
P44: ・ | Q44: 設計検査や妥当性確認の実績（実施日）の漏れや誤記が散見された。品質記録は品質管理を実施した重要な記録であるため、正しい月日が記載されているか？【2024年度】
P46: ・ | Q46: 初版の品質計画書の内容から変更が生じた場合は，変更理由を記載のうえ改訂し，最新版を用いて管理しているか？
...

Sheet 契約内容確認書
AF1: 参考帳票（2026/1/9）
B2: 契約内容確認書（1/2） | AS2: 目次へ戻る | AT2: =HYPERLINK("#目次!A1","●") -> ●
B3: 部長から引き継いだ受注関連情報，打合せから得られた要求事項 | AS3: フローへ戻る | AT3: =HYPERLINK("#フロー!A2","●") -> ●
B4: 顧客名 | E4: =+基本データ!D5 -> 東京電力HD | AE4: 受付日 | AS4: 改訂履歴
B5: 件名 | E5: =基本データ!D4 -> 〇〇設計業務委託 | AS5: 改訂日 | AT5: 改訂内容
B6: 確認者 | AS6: 44917 | AT6: 2022年度土木・ジオ本部内部監査指摘事項４か所反映（赤字部分）
B7: 受注関連情報 顧客要求事項 | E7: 【営業本部からの受領資料】 | AS7: 44988 | AT7: 未保有技術を外注する場合の対応に関する注意喚起のコメントを追記
E8: □ | F8: 業務受付処理票、 | L8: □ | M8: 積算書作成依頼（ | T8: □ | U8: 見積依頼書、 | Z8: □ | AA8: 仕様書、 | AD8: □ | AE8: 設計書） | AS8: 45043 | AT8: 書式修正
E9: □ | F9: その他（ ） | AS9: 45099 | AT9: 誤字の修正（規定→規程、実行書→実行承認）、押印枠の作成者→確認者
AS10: 45218 | AT10: チェック体制の区分を明記できるよう書式を変更（2023年度台湾内部監査指摘事項）
E11: ○発注内示書又は確認記録； | W11: □ | X11: Yes→（添付資料－ | AL11: ） | AM11: □ | AN11: No | AS11: 46031 | AT11: リスク評価の審議レベルの追加
E12: ○積算依頼書又は確認記録； | W12: □ | X12: Yes→（添付資料－ | AL12: ） | AM12: □ | AN12: No | AS12: 46031 | AT12: 表現の修正、チェックボックスのプルダウン選択化
E13: ○見積依頼書（仕様書，設計書）又は確認記録； | W13: □ | X13: Yes→（添付資料－ | AL13: ） | AM13: □ | AN13: No | AS13: 46031 | AT13: 全体をレビュー
E14: ○社会的要求事項（法令、基準等）の確認記録（議事録など）；
W15: □ | X15: Yes→（添付資料－ | AL15: ） | AM15: □ | AN15: No
E16: ○その他の確認記録（議事録,メール,メモ）； | W16: □ | X16: Yes→（添付資料－ | AL16: ） | AM16: □ | AN16: No
B19: 業務受付処理票あるいは積算書の作成依頼を受理してから積算書提出前に実施
B20: 顧客不満足発生リスクの確認 | E20: ・ | F20: 顧客要求事項（業務の内容，必要とする技術，工期等）に対して，これを満たす上での必要な技術を保有しているか？
AJ21: □ | AK21: Yes | AM21: □ | AN21: No
E23: ・ | F23: 必要な人材・体制を自部署で確保できるか？ | AJ23: □ | AK23: Yes | AM23: □ | AN23: No
E25: ・ | F25: 必要な物的資源（資機材，解析プログラム）を自部署で確保できるか？ | AJ25: □ | AK25: Yes | AM25: □ | AN25: No
E27: ・ | F27: 上項がNoの場合、すなわち、自部署で上記の資源を確保できない場合において，
F28: 本部内外の他部署あるいは委託先の協力により，解決できるか？ | AJ28: □ | AK28: Yes | AM28: □ | AN28: No
E30: ・ | F30: 上項がYesの場合、その協力先は？ | Z30: □ | AA30: 本部内 | AD30: □ | AE30: 本部外 | AH30: □ | AI30: 委託先 | AL30: □ | AM30: その他
F31: （委託する場合、下請法の適用に注意）
F32: （当社が未保有の技術（未保有プログラムを含む）を使用する業務を委託する場合は、業務品質管理要領（QC1-003）「10.1.2 留意事項」を参照。）
E35: ・ | F35: 原子力関連要領を適用するか？ | AJ35: □ | AK35: Yes | AM35: □ | AN35: No
E37: ・ | F37: 仕様書の内容が当社の不利益となる内容，あるいは内容の解釈によって顧客の不満足に繋がる内容はないか？
AJ38: □ | AK38: Yes | AM38: □ | AN38: No
AF51: =+AF1 -> 参考帳票（2026/1/9）
B52: 契約内容確認書（2/2）
B53: 業務受付処理票あるいは積算書の作成依頼を受理してから積算書提出前に実施
B54: 顧客不満足発生リスクの確認
E55: 契約前段階で想定されるリスクの確認・対応結果
F56: リスク対策を実施する場合、妥当性確認において、その対策の有効性を評価すること
E57: リスク項目 | J57: リスク項目詳細 | AE57: 対策 審議 | AG57: 有無 程度 | AI57: 対策 | AK57: 具体策
E59: 1.新規顧客 | J59: 新規顧客である場合、当社が要求事項の提示方法・業務推進方法に習熟しておらず、顧客の要求事項・要注意事項を見落とす。
E61: 2.新規商材 | J61: 新規商材である場合、ノウハウが十分ではなく案件形成の段階でのリスクを見逃す。
E63: 3.業務内容不明確 | J63: 顧客の要求事項が不明確で受注に進むべきか、手を引くかの判断に迷う間、当社から手を引けない状況となり不利な条件での受注を強いられる。
E65: 4.与信問題の発生 | J65: 技術方が独自に案件化を進め、契約の段階で営業方が与信調査をした結果、顧客の与信に問題があることが判明し、顧客との金銭面でのトラブルが発生する。【営業本部からの確認結果】
...

Sheet 記載例契約内容確認書
AF1: 参考帳票（2026/1/9）
B2: 契約内容確認書（1/2） | AS2: 目次へ戻る | AT2: =HYPERLINK("#目次!A2","●") -> ●
B3: 部長から引き継いだ受注関連情報，打合せから得られた要求事項 | AS3: フローへ戻る | AT3: =HYPERLINK("#フロー!A2","●") -> ●
B4: 顧客名 | E4: =+基本データ!D5 -> 東京電力HD | AE4: 受付日 | AS4: 改訂履歴
B5: 件名 | E5: =+基本データ!D4 -> 〇〇設計業務委託 | AS5: 改訂日 | AT5: 改訂内容
B6: 確認者 | AS6: 44917 | AT6: 2022年度土木・ジオ本部内部監査指摘事項４か所反映（赤字部分）
B7: 受注関連情報 顧客要求事項 | E7: 【営業本部からの受領資料】 | AS7: 44988 | AT7: 未保有技術を外注する場合の対応に関する注意喚起のコメントを追記
E8: ■業務受付処理票、■積算書作成依頼（■見積依頼書、■仕様書、■設計書） | AS8: 45043 | AT8: 書式修正
E9: □その他（ ） | AS9: 45099 | AT9: 誤字の修正（規定→規程、実行書→実行承認）、押印枠の作成者→確認者
AS10: 45218 | AT10: チェック体制の区分を明記できるよう書式を変更（2023年度台湾内部監査指摘事項）
E11: ○発注内示書又は確認記録； | W11: □ | X11: Yes→（添付資料－ | AL11: ） | AM11: □ | AN11: No | AS11: 45798 | AT11: リスク評価の審議レベルの追加
E12: ○積算依頼書又は確認記録； | W12: □ | X12: Yes→（添付資料－ | AL12: ） | AM12: □ | AN12: No | AS12: 46031 | AT12: 表現の修正、チェックボックスのプルダウン選択化
E13: ○見積依頼書（仕様書，設計書）又は確認記録； | W13: ■ | X13: Yes→（添付資料－1 見積依頼書一式 | AL13: ） | AM13: □ | AN13: No
E14: ○社会的要求事項（法令、基準等）の確認記録（議事録など）；
W15: □ | X15: Yes→（添付資料－ | AL15: ） | AM15: □ | AN15: No
E16: ○その他の確認記録（議事録,メール,メモ）； | W16: □ | X16: Yes→（添付資料－ | AL16: ） | AM16: □ | AN16: No
B19: 業務受付処理票あるいは積算書の作成依頼を受理してから積算書提出前に実施
B20: 顧客不満足発生リスクの確認 | E20: ・ | F20: 顧客要求事項（業務の内容，必要とする技術，工期等）に対して，これを満たす上での必要な技術を保有しているか？
AJ21: ■Yes □No
E22: ・ | F22: 必要な人材・体制を自部署で確保できるか？ | AJ22: ■Yes □No
E23: ・ | F23: 必要な物的資源（資機材，解析プログラム）を自部署で確保できるか？ | AJ23: ■Yes □No
E24: ・ | F24: 上項がNoの場合、すなわち、自部署で上記の資源を確保できない場合において，
F25: 本部内外の他部署あるいは委託先の協力により，解決できる | AJ25: □Yes □No
E26: ・ | F26: Yesのとき、その協力先は？ | Y26: □本部内 □本部外 □委託先 □その他
F27: （委託する場合、下請法の適用に注意）
F28: （当社が未保有の技術（未保有プログラムを含む）を使用する業務を委託する場合は、業務品質管理要領（QC1-003）「10.委託（2）委託仕様書作成の留意事項」を参照。）
E30: ・ | F30: 原子力関連要領を適用するか | AJ30: □Yes ■No
E31: ・ | F31: 仕様書の内容が当社の不利益となる内容，あるいは内容の解釈によって顧客の不満足に繋がる内容はない
AJ32: ■Yes □No
AF48: =+AF1 -> 参考帳票（2026/1/9）
B49: 契約内容確認書（2/2）
B50: 業務受付処理票あるいは積算書の作成依頼を受理してから積算書提出前に実施
B51: 顧客不満足発生リスクの確認
E52: 契約前段階で想定されるリスクの確認・対応結果
F53: リスク対策を実施する場合、妥当性確認において、その対策の有効性を評価すること
E54: リスク項目 | J54: リスク項目詳細 | AE54: 対策 審議 | AG54: 有無 程度 | AI54: 対策 | AK54: 具体策
E56: 1.新規顧客 | J56: 新規顧客である場合、当社が要求事項の提示方法・業務推進方法に習熟しておらず、顧客の要求事項・要注意事項を見落とす。 | AG56: ×
E58: 2.新規商材 | J58: 新規商材である場合、ノウハウが十分ではなく案件形成の段階でのリスクを見逃す。 | AG58: ×
E60: 3.業務内容不明確 | J60: 顧客の要求事項が不明確で受注に進むべきか、手を引くかの判断に迷う間、当社から手を引けない状況となり不利な条件での受注を強いられる。 | AG60: ×
E62: 4.与信問題の発生 | J62: 技術方が独自に案件化を進め、契約の段階で営業方が与信調査をした結果、顧客の与信に問題があることが判明し、顧客との金銭面でのトラブルが発生する。【営業本部からの確認結果】 | AG62: ×
...

Sheet 契約内容変更確認書
J1: 参考帳票（2026/1/9）
B2: 契約内容に変更が発生した場合（変更の都度確認のこと） | Q2: 目次へ戻る | R2: =HYPERLINK("#目次!A1","●") -> ●
B3: 契約内容変更確認書（No. ） | Q3: フローへ戻る | R3: =HYPERLINK("#フロー!A2","●") -> ●
B4: 件名コード | E4: =基本データ!D3 -> LG***** | Q4: 改訂履歴
B5: 件 名 | E5: =基本データ!D4 -> 〇〇設計業務委託 | Q5: 改訂日 | R5: 改訂内容
B6: 確認日/場所 | Q6: 44922 | R6: 設計変更時にもリスクの有無確認欄を追加
B7: お客様 | E7: =基本データ!D5 -> 東京電力HD | Q7: 45099 | R7: 誤字の修正（規定→規程、実行書→実行承認）、押印枠の作成者→確認者
B8: 確認者 | Q8: 45798 | R8: リスク評価の審議レベルの追加
C9: １．変更内容 | Q9: 46031 | R9: 表現の修正、チェックボックスのプルダウン選択化
C15: □ | D15: 資料で確認（資料名）：
C16: 注意： | D16: 積算書の承認は、以下のとおり。
D17: 見積額１億円以上；社長 ※）
D18: 見積額１億円未満～0.3 億円以上；本部長
D19: 見積額 0.3 億円未満；主管部長
D20: 見積額１億円以上の大型案件または本部長が必要と認めた場合は，「受注計画＊承認取扱要領 (BB1-008)」にしたがい，「承認書取扱要領（BS1-002）」の定める電子承認ワークフローシステムを用いて「受注計画書 (BB1-008-01) 」を作成し，「職務権限規程（AP1-004）」にしたがって承認を得る。
D23: ※）ここでいう「見積額」とは，「変更前の受注契約額に対する増分」のこと。
C25: ２．想定されるリスクの確認・対応結果
C26: □ | D26: 想定されるリスクの有無 | H26: □有 | I26: □無
C27: リスク対策を実施する場合、妥当性確認において、その対策の有効性を評価すること
C29: リスク項目 | E29: リスク項目詳細 | H29: 対策 審議 | I29: 有無 程度 | J29: 対策 | K29: 具体策
C40: 対策審議 各部；部会議、本部；本部会議、全社；リスク評価会議 | J40: 本部長 | K40: 部長 | L40: 実施責任者
C41: 有無程度 ×；該当しない、△；殆ど該当しない、○；一部該当する、
D42: ◎；殆ど該当する
C43: 対策 Ａ；回避、Ｂ；低減、Ｃ；移転、Ｄ；保有
C44: （書ききれない場合、別紙「リスク対策シート」に記載）

Sheet リスク対策シート
Z1: 参考帳票（2026/1/9）
B2: リスク対策シート | M2: 帳票番号 | AK2: 目次へ戻る | AL2: =HYPERLINK("#目次!A1","●") -> ●
M3: 規定文書名 | T3: 受注業務のリスク管理方法の指針 | AK3: フローへ戻る | AL3: =HYPERLINK("#フロー!A2","●") -> ●
M4: 本部内主管箇所 | AD4: 本部
Z5: 部 | AF5: G | AK5: 改訂履歴
B6: □契約前・□契約後 | T6: 発行年月日： | AK6: 改訂日 | AL6: 改訂内容
B7: 件名： | H7: =基本データ!D4 -> 〇〇設計業務委託 | AK7: 46031 | AL7: 体裁見直し
B8: 顧客名： | H8: =基本データ!D5 -> 東京電力HD
B9: 受注期間： | H9: =基本データ!D6 -> 45017 | N9: ～ | O9: =基本データ!D7 -> 45382 | U9: 受注額： | X9: =+基本データ!D11/1000000 -> 5 | AD9: 百万円
B10: 実施責任者： | H10: 東設 三郎
C11: ■背景と経緯
C17: ■リスクの詳細内容
C23: ■対策（当該リスク対策を■に変更する） □回避 □低減 □移転 □保有
C28: ■対策の有効性評価（業務完了後に記載）
C33: 承認欄 | Q33: 本部長 | U33: 部長 | Y33: GM | AC33: 実施責任者
C35: 「対策」の承認
C39: 承認欄 | Q39: 本部長 | U39: 部長 | Y39: GM | AC39: 実施責任者
C41: 「対策の有効性」の評価

Sheet リスク評価シート
U1: 参考帳票（2026/1/9）
B2: 受注案件リスク評価シート | O2: 回答欄凡例
C3: 案件番号： | D3: =+基本データ!D3 -> LG***** | O3: ◎ | P3: ：大いに当てはまる | Z3: 目次へ戻る | AA3: =HYPERLINK("#目次!A1","●") -> ●
C4: 案 件 名： | D4: =+基本データ!D4 -> 〇〇設計業務委託 | O4: ○ | P4: ：一部当てはまる | Z4: フローへ戻る | AA4: =HYPERLINK("#フロー!A2","●") -> ●
O5: △ | P5: ：ほとんど当てはまらない
C6: お客さま名： | D6: =+基本データ!D5 -> 東京電力HD | O6: × | P6: ：該当なし | Z6: 改訂履歴
C7: 受注金額： | D7: =+基本データ!D11 -> 5000000 | Z7: 改訂日 | AA7: 改訂内容
D8: 赤枠内に必要情報を記入 | Z8: 46031 | AA8: 新規制定
B9: 【リスク評価ＳＴＥＰ１】 | R9: ウエイト記入
C10: リスク項目 | F10: リスク項目詳細 | O10: 回答 | P10: 備考 | R10: 項目 ウエイト | S10: 回答内容 | T10: 回答箇所
B11: 1.契約前段階で想定されるリスク | C11: ①新規お客さま | F11: 新規お客さまである場合、当社が要求事項の提示方法・業務推進方法に習熟しておらず、お客さまの要求事項・要注意事項を見落とす。 | O11: ◎ | R11: 1 | S11: =IF(O11="",0,IF(O11="◎",3,IF(O11="〇",2,IF(O11="△",1,IF(O11="×",0)))))*R11 -> 3 | T11: =IF(O11="",0,IF(O11="◎",1,IF(O11="○",1,IF(O11="△",1,IF(O11="×",1)))))*R11 -> 1
C12: ②新規商材 | F12: 新規商材である場合、ノウハウが十分ではなく案件形成の段階でのリスクを見逃す。 | O12: 〇 | R12: 1 | S12: =IF(O12="",0,IF(O12="◎",3,IF(O12="〇",2,IF(O12="△",1,IF(O12="×",0)))))*R12 -> 2 | T12: =IF(O12="",0,IF(O12="◎",1,IF(O12="○",1,IF(O12="△",1,IF(O12="×",1)))))*R12 -> 0
C13: ③業務内容不明確 | F13: お客さまの要求事項が不明確で受注に進むべきか、手を引くかの判断に迷う間、当社から手を引けない状況となり不利な条件での受注を強いられる。 | O13: △ | R13: 1 | S13: =IF(O13="",0,IF(O13="◎",3,IF(O13="〇",2,IF(O13="△",1,IF(O13="×",0)))))*R13 -> 1 | T13: =IF(O13="",0,IF(O13="◎",1,IF(O13="○",1,IF(O13="△",1,IF(O13="×",1)))))*R13 -> 1
C14: ④与信問題の発生 | F14: 技術方が独自に案件化を進め、契約の段階で営業方が与信調査をした結果、お客さまの与信に問題があることが判明し、お客さまとの金銭面でのトラブルが発生する。 | O14: × | R14: 1 | S14: =IF(O14="",0,IF(O14="◎",3,IF(O14="〇",2,IF(O14="△",1,IF(O14="×",0)))))*R14 -> 0 | T14: =IF(O14="",0,IF(O14="◎",1,IF(O14="○",1,IF(O14="△",1,IF(O14="×",1)))))*R14 -> 1
C15: ⑤契約内容の突然の変更 | F15: （特命型）担当者と合意形成を行って来た内容が、相手都合（上司の指示等）により、契約間際に覆ってしまう。（競争型）仕様内容が不明確なまま受注し、追加業務をさせられる。 | O15: △ | R15: 1 | S15: =IF(O15="",0,IF(O15="◎",3,IF(O15="〇",2,IF(O15="△",1,IF(O15="×",0)))))*R15 -> 1 | T15: =IF(O15="",0,IF(O15="◎",1,IF(O15="○",1,IF(O15="△",1,IF(O15="×",1)))))*R15 -> 1
C16: ⑥工期のお客さま都合の変更 | F16: 想定していた工期・納期が、お客さま都合により変更となってしまい、変更後の着手段階で十分なリソースを確保できないまま業務実施を求められる。 | O16: × | R16: 1 | S16: =IF(O16="",0,IF(O16="◎",3,IF(O16="〇",2,IF(O16="△",1,IF(O16="×",0)))))*R16 -> 0 | T16: =IF(O16="",0,IF(O16="◎",1,IF(O16="○",1,IF(O16="△",1,IF(O16="×",1)))))*R16 -> 1
C17: ⑦確認記録の不備 | F17: 電話連絡で受けた情報等を記録に残さなかったため、お客さまとの間で要求内容の認識に齟齬が生じ、トラブルに発展する。 | O17: × | R17: 1 | S17: =IF(O17="",0,IF(O17="◎",3,IF(O17="〇",2,IF(O17="△",1,IF(O17="×",0)))))*R17 -> 0 | T17: =IF(O17="",0,IF(O17="◎",1,IF(O17="○",1,IF(O17="△",1,IF(O17="×",1)))))*R17 -> 1
C18: ⑧金額不足 | F18: 当初の見積もり額より、判明した最終的な見積もり額が上振れした場合、客先が受け入れを拒む。 | O18: × | R18: 1 | S18: =IF(O18="",0,IF(O18="◎",3,IF(O18="〇",2,IF(O18="△",1,IF(O18="×",0)))))*R18 -> 0 | T18: =IF(O18="",0,IF(O18="◎",1,IF(O18="○",1,IF(O18="△",1,IF(O18="×",1)))))*R18 -> 1
C19: ⑨損害賠償の上限 | F19: 契約書などに設計瑕疵などによる損害賠償に関する記載がない（上限がない）ため、重大な設計瑕疵により損害賠償が生じた場合、支払いができなくなる可能性がある。 | O19: ◎ | R19: 1 | S19: =IF(O19="",0,IF(O19="◎",3,IF(O19="〇",2,IF(O19="△",1,IF(O19="×",0)))))*R19 -> 3 | T19: =IF(O19="",0,IF(O19="◎",1,IF(O19="○",1,IF(O19="△",1,IF(O19="×",1)))))*R19 -> 1
C20: ⑩その他 | O20: ◎ | R20: 1 | S20: =IF(O20="",0,IF(O20="◎",3,IF(O20="〇",2,IF(O20="△",1,IF(O20="×",0)))))*R20 -> 3 | T20: =IF(O20="",0,IF(O20="◎",1,IF(O20="○",1,IF(O20="△",1,IF(O20="×",1)))))*R20 -> 1
R21: =IF(S21=0,"",S21/T21) -> 0.48148148 | S21: =SUM(S11:S20) -> 13 | T21: =SUM(T11:T20)*3 -> 27
D22: 評価数 | E22: 全体 | F22: 評価率 | G22: 【ＳＴＥＰ１のリスク評価結果】
B23: リスク１ | D23: =S21 -> 13 | E23: =T21 -> 27 | F23: =IF(D23=0,"",D23/E23) -> 0.48148148 | G23: =IF(F23="","",IF(F23>=D25,"評価率によるリスクは大です",IF(F23>=D26,"評価率によるリスクは中です",IF(F23>=D27,"評価率によるリスクは小です",IF(F23>0,"評価率によるリスクは極めて小です"))))) -> 評価率によるリスクは小です
F24: 【評価】
B25: 高 | C25: リスク大 | D25: 0.8 | F25: 実施責任者氏名 | N25: 部長氏名
B26: 中 | C26: リスク中 | D26: 0.5 | F26: 記入日 | H26: 45961 | N26: 記入日 | P26: 45961
B27: 低 | C27: リスク小 | D27: 0.2 | F27: 自由記載欄 | N27: 管理の重要度 高/中/低を記載 | P27: 低
C28: リスク極小
B30: 【リスク評価ＳＴＥＰ２】
C31: リスク項目 | F31: リスク項目詳細 | O31: 回答 | P31: 備考 | R31: 項目 ウエイト | S31: 回答内容 | T31: 回答箇所
B32: 2.受注・業務着手段階で想定されるリスク | C32: ①確認記録の不備 | F32: 案件形成時に認識していた要求事項と契約時の要求事項に差異が発生し、当社がエビデンスを提示することが出来ず、お客さまの要求に従わざるを得ない。 | O32: △ | R32: 1 | S32: =IF(O32="",0,IF(O32="◎",3,IF(O32="〇",2,IF(O32="△",1,IF(O32="×",0)))))*R32 -> 1 | T32: =IF(O32="",0,IF(O32="◎",1,IF(O32="○",1,IF(O32="△",1,IF(O32="×",1)))))*R32 -> 1
C33: ②お客さま要求事項の未確定による作業の手戻り | F33: 受注時でもなお、要求事項が不明確である中で業務を着手せざるを得ず、作業の手戻りが発生したり、工期を順守できなくなる。 | O33: △ | R33: 1 | S33: =IF(O33="",0,IF(O33="◎",3,IF(O33="〇",2,IF(O33="△",1,IF(O33="×",0)))))*R33 -> 1 | T33: =IF(O33="",0,IF(O33="◎",1,IF(O33="○",1,IF(O33="△",1,IF(O33="×",1)))))*R33 -> 1
C34: ③業務内容不明確 | F34: 品質計画（書）策定段階でのリスク抽出が出来なかった場合、見逃したリスクが後の業務実施段階で支障をきたす。 | O34: × | R34: 1 | S34: =IF(O34="",0,IF(O34="◎",3,IF(O34="〇",2,IF(O34="△",1,IF(O34="×",0)))))*R34 -> 0 | T34: =IF(O34="",0,IF(O34="◎",1,IF(O34="○",1,IF(O34="△",1,IF(O34="×",1)))))*R34 -> 1
C35: ④委託先の成果品不良、工程遅延 | F35: 委託先の選定を誤り（初めての会社、規模の小さい会社、地元企業等）、委託先への条件提示の遅れに対し委託先でその遅れを吸収できずに工期が遅れ、当社も発注者に対し工期不履行となる。技術面でも同様のリスク。 | O35: × | R35: 1 | S35: =IF(O35="",0,IF(O35="◎",3,IF(O35="〇",2,IF(O35="△",1,IF(O35="×",0)))))*R35 -> 0 | T35: =IF(O35="",0,IF(O35="◎",1,IF(O35="○",1,IF(O35="△",1,IF(O35="×",1)))))*R35 -> 1
C36: ⑤ | R36: 1 | S36: =IF(O36="",0,IF(O36="◎",3,IF(O36="〇",2,IF(O36="△",1,IF(O36="×",0)))))*R36 -> 0 | T36: =IF(O36="",0,IF(O36="◎",1,IF(O36="○",1,IF(O36="△",1,IF(O36="×",1)))))*R36 -> 0
C37: ⑥ | R37: 1 | S37: =IF(O37="",0,IF(O37="◎",3,IF(O37="〇",2,IF(O37="△",1,IF(O37="×",0)))))*R37 -> 0 | T37: =IF(O37="",0,IF(O37="◎",1,IF(O37="○",1,IF(O37="△",1,IF(O37="×",1)))))*R37 -> 0
C38: ⑦ | R38: 1 | S38: =IF(O38="",0,IF(O38="◎",3,IF(O38="〇",2,IF(O38="△",1,IF(O38="×",0)))))*R38 -> 0 | T38: =IF(O38="",0,IF(O38="◎",1,IF(O38="○",1,IF(O38="△",1,IF(O38="×",1)))))*R38 -> 0
C39: ⑧ | R39: 1 | S39: =IF(O39="",0,IF(O39="◎",3,IF(O39="〇",2,IF(O39="△",1,IF(O39="×",0)))))*R39 -> 0 | T39: =IF(O39="",0,IF(O39="◎",1,IF(O39="○",1,IF(O39="△",1,IF(O39="×",1)))))*R39 -> 0
C40: ⑨ | R40: 1 | S40: =IF(O40="",0,IF(O40="◎",3,IF(O40="〇",2,IF(O40="△",1,IF(O40="×",0)))))*R40 -> 0 | T40: =IF(O40="",0,IF(O40="◎",1,IF(O40="○",1,IF(O40="△",1,IF(O40="×",1)))))*R40 -> 0
C41: ⑩ | R41: 1 | S41: =IF(O41="",0,IF(O41="◎",3,IF(O41="〇",2,IF(O41="△",1,IF(O41="×",0)))))*R41 -> 0 | T41: =IF(O41="",0,IF(O41="◎",1,IF(O41="○",1,IF(O41="△",1,IF(O41="×",1)))))*R41 -> 0
...

Sheet 受注計画書
U1: BB1-008-(2)-01 | Y1: 2025年度 受注計画書の⼈件費単価と間接原価 | AD1: ←ユニットHPへのリンクです
B2: 承認日 | F2: 作成日 | J2: 通知日 | T2: 通知日
C3: ( ／ ／ ) | H3: ( ／ ／ ) | K3: ( ／ ／ ) | U3: ( ／ ／ ) | Y3: ◇承認書例４：受注計画書(チェックリスト付き) ver.6 （総括作成） | AE3: ←ユニットHPへのリンクです
B4: 社長 | C4: 本部長 | D4: 部長 | F4: ＧＭ | K4: 常任監査役 | U4: 見積書/入札書 作成箇所 | Y4: 要領抜粋 | AO4: 目次へ戻る | AP4: =HYPERLINK("#目次!A2","●") -> ●
AO5: フローへ戻る | AP5: =HYPERLINK("#フロー!A2","●") -> ●
P6: 本部 | T6: 部 | AO6: 改訂履歴
AO7: 改訂日 | AP7: 改訂内容
I8: 受 注 計 画 書 | AO8: 46031 | AP8: 新規追加
B9: １． 受 注 計 画 概 要 | V9: （千円）
B10: 件名コード | D10: =基本データ!D3 -> LG***** | M10: 主管部 | Q10: 本部 | T10: 部
B11: 件名名称 | D11: =基本データ!D4 -> 〇〇設計業務委託 | M11: 依頼部 | Q11: 本部 | T11: 部
M12: 依頼部 | Q12: 本部 | T12: 部
B13: 受注先 | D13: =基本データ!D5 -> 東京電力HD | T13: 受注総額 | U13: =SUM(U10:U12) -> 0
B15: ２． 実 行 計 画 （ 設計監理原価 ）
B16: 項 目 | F16: 原 実 施 計 画 | M16: 変 更 計 画 | T16: 増 減 | AO16: 使用時は最新版を確認すること（受注計画承認取扱要領（BB1-008））
F17: 内 容 | J17: 金 額（千円） | M17: 内 容 | Q17: 金 額（千円）
B18: 受 注 額 (A) | U18: =R18-K18 -> 0 | V18: 0
B19: 契約工期 (全体) | F19: =基本データ!D6 -> 45017 | J19: ～ | K19: =基本データ!D7 -> 45382 | Q19: ～ | U19: 0 | V19: 0
B20: 人 件 費 | G20: × | I20: 人日 | K20: =F20*H20 -> 0 | N20: × | P20: 人日 | R20: =M20*O20 -> 0 | U20: =R20-K20 -> 0 | V20: 0
B21: 委 託 費 （技術出向・労働派遣等） | U21: =R21-K21 -> 0 | V21: 0
U22: =R22-K22 -> 0 | V22: 0
F23: 計 | K23: =SUM(K21:L22) -> 0 | M23: 計 | R23: =SUM(R21:S22) -> 0 | U23: =R23-K23 -> 0 | V23: 0
B24: 設計委託費 (B) | U24: =R24-K24 -> 0 | V24: 0
U25: =R25-K25 -> 0
U26: =R26-K26 -> 0 | V26: 0
U27: =R27-K27 -> 0 | V27: 0
U28: =R28-K28 -> 0 | V28: 0
U29: =R29-K29 -> 0 | V29: 0
U30: =R30-K30 -> 0 | V30: 0
U31: =R31-K31 -> 0 | V31: 0
F32: 計 | K32: =SUM(K24:L31) -> 0 | M32: 計 | R32: =SUM(R24:S31) -> 0 | U32: =R32-K32 -> 0 | V32: 0
B33: 直接経費 | U33: =R33-K33 -> 0 | V33: 0
U34: =R34-K34 -> 0 | V34: 0
U35: =R35-K35 -> 0 | V35: 0
U36: =R36-K36 -> 0 | V36: 0
F37: 計 | K37: =SUM(K33:L36) -> 0 | M37: 計 | R37: =SUM(R33:S36) -> 0 | U37: =R37-K37 -> 0 | V37: 0
B38: 間接原価((人件費+委託費) 間接原価算出予定比率) | U38: =R38-K38 -> 0 | V38: 0
B39: 合 計 (C) | K39: =SUM(K20,K23,K32,K37,K38) -> 0 | R39: =SUM(R20,R23,R32,R37,R38) -> 0 | U39: =R39-K39 -> 0 | V39: 0
B40: 設計委託率 (B)/(A) | K40: =IF(ISERROR(K32/K18*100),"",K32/K18*100) | L40: ％ | R40: =IF(ISERROR(R32/R18*100),"",R32/R18*100) | S40: ％
B41: 粗 利 益 (A)-(C) | K41: =K18-K39 -> 0 | R41: =R18-R39 -> 0
...

Sheet 品質計画書
AZ1: 参考帳票（2026/1/9）
B2: 品 質 計 画 書（No. ） | BF2: 目次へ戻る | BG2: =HYPERLINK("#目次!A2","●") -> ●
BF3: フローへ戻る | BG3: =HYPERLINK("#フロー!A2","●") -> ●
B4: 業務概要 | AL4: 業務工程
B5: 件名コード | H5: =基本データ!D3 -> LG***** | AL5: 項 目 | AM5: 担当者 | AN5: 年 度 | BF5: 改訂履歴
B6: 受注件名 | H6: =基本データ!D4 -> 〇〇設計業務委託 | AN6: 前年度 | AO6: 4 | AP6: 5 | AQ6: 6 | AS6: 7 | AT6: 8 | AU6: 9 | AV6: 10 | AW6: 11 | AX6: 12 | AY6: 1 | AZ6: 2 | BA6: 3 | BB6: 次年度 | BF6: 改訂日 | BG6: 改訂内容
B7: 受注先 | H7: =基本データ!D5 -> 東京電力HD | BF7: 44957 | BG7: 変更理由欄にコメント追記
B8: 受託期間 | H8: =基本データ!D6 -> 45017 | U8: ～ | Y8: =基本データ!D7 -> 45382 | BF8: 44987 | BG8: 技術プログラムの使用の有無欄にコメント追記
B9: 業務構成 | BF9: 45043 | BG9: 2022年度内部監査指摘事項に対する対応
B10: チェック 体制 | H10: □ A-? 体制 | N10: □ B-? 体制 | T10: □ C 体制 | AJ10: ；体制を選択する | BF10: 45218 | BG10: チェック体制の区分を明記できるよう書式を変更（2023年度台湾内部監査指摘事項）
H11: □ 上記以外の特別な体制（理由を記載し、本部長の承認が必要） | BF11: 45309 | BG11: リスク管理欄の文書を見直し（帳票をレビュー）
I12: （理由： 本部長印） | BF12: 45839 | BG12: リスク評価の審議レベルの追加
BF13: 45839 | BG13: 表現の修正、チェックボックスのプルダウン選択化
H14: 承 認 者 | Q14: =基本データ!D8 -> 東設 太郎 | BF14: 46031 | BG14: 全体をレビュー
H15: 審 査 者 | Q15: =基本データ!D9 -> 東設 次郎
H16: 実 施 責 任 者 | Q16: =基本データ!D10 -> 東設 三郎
H17: 担当者
B19: 部間／本部間依頼 | H19: No. | Q19: ① | X19: ② | AE19: ③ | AL19: 進捗管理
H20: 所属 | AL20: 主要技術検討会
H21: 担当者 | AL21: 委託成果品検査
B22: 委託先 | H22: No. | Q22: ① | X22: ② | AE22: ③ | AL22: 設計検査
H23: 会社名 | AL23: 妥当性確認
H24: 所属 | AL24: 受注業務のリスク管理
H25: 担当者 | AL25: 契約前段階で想定されるリスクの確認・対応結果（すでに契約内容確認書で挙げているリスク項目がある場合、それを再掲）
H26: ※委託先からの実施計画書： | Q26: □有 | U26: □無 | X26: □有 | AB26: □無 | AE26: □有 | AI26: □無 | AL26: リスク項目 | AO26: リスク項目詳細 | AX26: 対策審議 | AY26: 有無程度 | AZ26: 対策 | BA26: 具体策
H28: 有の場合：委託仕様書の内容が全て実施計画書に反映されている： | Q28: □ | X28: □ | AE28: □
B31: 業務実施 計画 | H31: 【実施項目・数量・内容】 | AL31: 受注・業務着手時段階で想定されるリスクの確認・対応結果
H32: ○実施内容、手順等を記載。記載しきれない場合は参照先を明記。 | AL32: リスク項目 | AO32: リスク項目詳細 | AX32: 対策審議 | AY32: 有無程度 | AZ32: 対策 | BA32: 具体策
AL33: 1.確認記録の不備 | AO33: 案件形成時に認識していた要求事項と契約時の要求事項に差異が発生し、当社がエビデンスを提示することが出来ず、顧客の要求に従わざるを得ない。
AL35: 2.顧客要求事項の未確定による作業の手戻り | AO35: 受注時でもなお、要求事項が不明確である中で業務を着手せざるを得ず、作業の手戻りが発生したり、工期を順守できなくなる。
AL37: 3.作業内容不明確 | AO37: 品質計画（書）策定段階でのリスク抽出が出来なかった場合、見逃したリスクが後の業務実施段階で支障をきたす。
AL39: 4.委託先の成果品不良、工程遅延 | AO39: 委託先の選定を誤り（初めての会社、規模の小さい会社、地元企業等）、委託先への条件提示の遅れに対し委託先でその遅れを吸収できずに工期が遅れ、当社も発注者に対し工期不履行となる。技術面でも同様のリスク。
AL41: 5.その他
AL43: 業務実施・引渡し段階で想定されるリスクの確認・対応結果
AL44: リスク項目 | AO44: リスク項目詳細 | AX44: 対策審議 | AY44: 有無程度 | AZ44: 対策 | BA44: 具体策
AL45: 1.設計変更時の検証不足 | AO45: 顧客の要求事項に変更があった場合、新規設計時と同じレビュー・検証を実施せず、顧客要求事項を満たさない成果品を提出してしまう。また、実施したとしても、設計上のミスを見逃してしまい、竣工後顧客に損害を与えてしまう。
AL47: 2. 業務進捗後、成果品が顧客のイメージと合わず、追加業務が発生 | AO47: 中間打合せで、着手した業務内容や変更内容が顧客の要求に合わず、想定外に工数・時間を要し、要求納期を守れない、コストが大幅に超過する等トラブルが発生する。
H49: ・技術プログラムリスト登録プログラムの使用（委託先を含む＊)： | AG49: □有 □無 | AL49: 3. 最終成果品が顧客のイメージと合わず、追加業務が発生 | AO49: 最終成果品が顧客の要求に合わず、想定外に工数・時間を要し、要求納期を守れない、コストが大幅に超過する等トラブルが発生する。
H50: 有の場合（名称： Ver. ）
AL51: 4.中間検査の未実施 | AO51: 中間検査を実施しなかったために出戻りが発生し、納期・工数に大きなインパクトを与える。
...

Sheet 【記載例】品質計画書
AJ1: 参考帳票（2026/1/9）
B2: 品 質 計 画 書（No. ） | AP2: 目次へ戻る | AQ2: =HYPERLINK("#目次!A2","●") -> ●
AP3: フローへ戻る | AQ3: =HYPERLINK("#フロー!A2","●") -> ●
B4: 業務概要 | V4: 業務工程
B5: 件名コード | H5: AC11111 | V5: 項 目 | X5: 年 度 | AP5: 改訂履歴
B6: 受注件名 | H6: 〇〇発電所の冷却用水路実施設計 | X6: 前年度 | Y6: 4 | Z6: 5 | AA6: 6 | AC6: 7 | AD6: 8 | AE6: 9 | AF6: 10 | AG6: 11 | AH6: 12 | AI6: 1 | AJ6: 2 | AK6: 3 | AL6: 次年度 | AP6: 改訂日 | AQ6: 改訂内容
B7: 受注先 | H7: 東京電力HD | V7: ①設計１（実施責任者） | AP7: 44957 | AQ7: 変更理由欄にコメント追記
B8: 受託期間 | H8: 44302 | R8: ～ | T8: 44645 | V8: 解析手法の妥当性検討 | AP8: 44987 | AQ8: 技術プログラムの使用の有無欄にコメント追記
B9: 業務構成 | V9: 測定装置仕様の検討 | AP9: 45043 | AQ9: 2022年度内部監査指摘事項に対する対応
B10: チェック 体制 | H10: ■体制Ａ-（３） □体制Ｂ-（ ） ；体制は番号まで記載 □原則以外（理由： 本部長印） | V10: ②設計２（担当者A） | AP10: 45218 | AQ10: チェック体制の区分を明記できるよう書式を変更（2023年度台湾内部監査指摘事項）
V11: ゆるみ領域の影響検討 | AP11: 45839 | AQ11: リスク管理欄の文書を見直し（帳票をレビュー）
H12: 承 認 者 | Q12: 東設 太郎 | V12: 引き戻し解析手法の検討 | AP12: 45839 | AQ12: リスク評価の審議レベルの追加
H13: 審 査 者 | Q13: 東設 次郎 | V13: ③技術オプション（担当者B） | AP13: 46031 | AQ13: 全体をレビュー
H14: 実 施 責 任 者 | Q14: 東設 三郎 | V14: （性能評価） 感度解析
H15: 担当者 | Q15: 担当者A | S15: 担当者B | U15: 担当者C | V15: 指標の検討
Q16: 担当者D | S16: 担当者E | V16: ドラフト作成
B17: 部間／本部間依頼 | H17: No. | Q17: ① | S17: ② | U17: ③ | V17: 報告書作成
H18: 所属 | V18: 委員会 | AC18: 7/20▼ | AG18: ▽ | AJ18: ▽
H19: 担当者 | V19: 進捗管理 | AA19: 6/25▼ | AE19: ▼9/15
B20: 委託先 | H20: No. | Q20: ① | S20: ② | U20: ③ | V20: 主要技術検討会
H21: 会社名 | V21: 委託成果品検査 | X21: →委託がある場合も同様に検査予定を記載し、実施したら実施日を記載する
H22: 所属 | V22: 設計検査 | AC22: ▼7/6,7/13委員会対応 | AG22: ▽委員会対応 | AI22: ▽ドラフト | AJ22: ▽委員会対応 | AK22: ▽中間
H23: 担当者 | V23: 妥当性確認 | AK23: ▽中間
H24: ※委託先からの実施計画書： | Q24: 有，無 | S24: 有，無 | U24: 有，無 | V24: 受注業務のリスク管理
V25: 契約前段階で想定されるリスクの確認・対応結果（すでに契約内容確認書で挙げているリスク項目がある場合、それを再掲）
H26: 有の場合：委託仕様書の内容が全て計画書に反映されている： | Q26: □ | S26: □ | U26: □ | V26: リスク項目 | Y26: リスク項目詳細 | AH26: 対策審議 | AI26: 有無程度 | AJ26: 対策 | AK26: 具体策
B31: 業務実施 計画 | H31: 【実施項目・数量・内容】 | V31: 受注・業務着手時段階で想定されるリスクの確認・対応結果
H32: 〇実施内容、手順等を記載。記載しきれない場合は参照先を明記。 | V32: リスク項目 | Y32: リスク項目詳細 | AH32: 対策審議 | AI32: 有無程度 | AJ32: 対策 | AK32: 具体策
I33: ・ | J33: 実施項目、実施方法、実施手順は〇〇発電所の冷却用水路実施設計実施計画書を参照。 | V33: 1.確認記録の不備 | Y33: 案件形成時に認識していた要求事項と契約時の要求事項に差異が発生し、当社がエビデンスを提示することが出来ず、顧客の要求に従わざるを得ない。 | AI33: × | AJ33: －
V35: 2.顧客要求事項の未確定による作業の手戻り | Y35: 受注時でもなお、要求事項が不明確である中で業務を着手せざるを得ず、作業の手戻りが発生したり、工期を順守できなくなる。 | AI35: 〇 | AJ35: D | AK35: お客様に要求事項の未確定による工程への影響を説明しこれを記録に残す
V37: 3.作業内容不明確 | Y37: 品質計画（書）策定段階でのリスク抽出が出来なかった場合、見逃したリスクが後の業務実施段階で支障をきたす。 | AI37: × | AJ37: －
V39: 4.委託先の成果品不良、工程遅延 | Y39: 委託先の選定を誤り（初めての会社、規模の小さい会社、地元企業等）、委託先への条件提示の遅れに対し委託先でその遅れを吸収できずに工期が遅れ、当社も発注者に対し工期不履行となる。技術面でも同様のリスク。 | AI39: × | AJ39: －
V41: 5.その他 | AI41: － | AJ41: －
V43: 業務実施・引渡し段階で想定されるリスクの確認・対応結果
V44: リスク項目 | Y44: リスク項目詳細 | AH44: 対策審議 | AI44: 有無程度 | AJ44: 対策 | AK44: 具体策
V45: 1.設計変更時の検証不足 | Y45: 顧客の要求事項に変更があった場合、新規設計時と同じレビュー・検証を実施せず、顧客要求事項を満たさない成果品を提出してしまう。また、実施したとしても、設計上のミスを見逃してしまい、竣工後顧客に損害を与えてしまう。 | AI45: × | AJ45: －
V47: 2. 業務進捗後、成果品が顧客のイメージと合わず、追加業務が発生 | Y47: 中間打合せで、着手した業務内容や変更内容が顧客の要求に合わず、想定外に工数・時間を要し、要求納期を守れない、コストが大幅に超過する等トラブルが発生する。 | AI47: × | AJ47: －
H49: ・技術プログラムリスト登録プログラムの使用（委託先を含む＊）： 有・無 | V49: 3. 最終成果品が顧客のイメージと合わず、追加業務が発生 | Y49: 最終成果品が顧客の要求に合わず、想定外に工数・時間を要し、要求納期を守れない、コストが大幅に超過する等トラブルが発生する。 | AI49: × | AJ49: －
H50: 有の場合（名称：Soil Pius Static/Flow Ver.2019、 三次元粒状体挙動解析 PFC3D Ver.4.0 ）
V51: 4.中間検査の未実施 | Y51: 中間検査を実施しなかったために出戻りが発生し、納期・工数に大きなインパクトを与える。 | AI51: × | AJ51: －
...

Sheet 特定業務品質計画書
M1: 参考帳票（2026/1/9）
B2: 特定業務品質計画書（No. ） | U2: 目次へ戻る | V2: =HYPERLINK("#目次!A2","●") -> ●
B3: 業務概要 | U3: フローへ戻る | V3: =HYPERLINK("#フロー!A2","●") -> ●
B4: 件名コード | C4: =基本データ!D3 -> LG***** | F4: 受託期間 | H4: =基本データ!D6 -> 45017 | L4: ～ | M4: =基本データ!D7 -> 45382
B5: 受注件名 | C5: =基本データ!D4 -> 〇〇設計業務委託 | U5: 改訂履歴
B6: 受注先 | C6: =基本データ!D5 -> 東京電力HD | U6: 改訂日 | V6: 改訂内容
B7: 業務構成 | U7: 44957 | V7: 変更理由欄にコメント追記
B8: チェック体制 | C8: 承認者 氏 名 | F8: 審査者 氏 名 | I8: 実施責任者 氏 名 | L8: 担当者 氏 名 | U8: 45043 | V8: 2022年度内部監査指摘事項に対する対応
C9: =基本データ!D8 -> 東設 太郎 | F9: =基本データ!D9 -> 東設 次郎 | I9: =基本データ!D10 -> 東設 三郎 | U9: 45839 | V9: リスク評価の審議レベルの追加
U10: 45839 | V10: 表現の修正、チェックボックスのプルダウン選択化
U11: 46031 | V11: 全体をレビュー
B12: 部間／本部間 依頼 | C12: 所属 | L12: 担当者 氏 名
B15: 委託先 | C15: 会社名 | G15: 所属 | L15: 担当者 氏 名
C17: ※委託先からの実施計画書： | F17: □有 □無 | H17: 有の場合：委託仕様書の内容が全て実施計画書に反映されている： | Q17: □
C19: ※委託先からの実施計画書： | F19: □有 □無 | H19: 有の場合：委託仕様書の内容が全て実施計画書に反映されている： | Q19: □
B20: 業務実施計画 | C20: 【実施項目・数量・内容】○実施内容、手順等を記載。記載しきれない場合は参照先を明記。
C27: ・技術プログラムリスト登録プログラムの使用（委託先を含む＊)： | K27: □有 | L27: (名称： Ver. ) | Q27: □無
C28: ＊；当社が未保有のプログラムを使用する業務を委託する場合は、業務品質管理要領（QC1-003）「10.委託（2）委託仕様書 作成の留意事項」を参照。
C29: ・必要不可欠な関連法令・規制： | G29: □有 | H29: (名称： ) | Q29: □無
C30: ・顧客が定めた規程・基準等 ： | G30: □有 | H30: (名称： ) | Q30: □無
C31: ・計画書等に地図・書籍等の転載： | H31: □有 | I31: (出所・出典が記載されている：□) | Q31: □無
C32: ・個人情報（自宅の住所，電話番号，運転免許証写し等）を持たざるを得ない： | O32: □有 | Q32: □無
C33: 「有」の場合： | F33: 実施担当者は個人情報管理台帳に記載して個人情報管理責任者(個人情報管理担当者)に報告すると共に，個人情報を記録した重要な書類等については，実施責任者が施錠保管している：□
B36: 業務工程
B37: 項 目 | C37: 年度
C38: 前年度 | D38: 4 | E38: 5 | F38: 6 | G38: 7 | H38: 8 | I38: 9 | J38: 10 | K38: 11 | L38: 12 | M38: 1 | N38: 2 | O38: 3 | P38: 次年度
B44: 委託成果品検査
B45: 妥当性確認
B46: 作成確認
B47: 変更理由/備考 （特定業務品質計画書を変更する場合、変更理由を必ず記載すること） | I47: 承認者 | K47: 審査者 | M47: 実施責任者 | O47: 作成者
M53: =M1 -> 参考帳票（2026/1/9）
B54: 特定業務品質計画書（引き続き）
B55: 受注業務のリスク管理
B56: 契約前段階で想定されるリスクの確認・対応結果（すでに契約内容確認書で実施したリスク評価の結果を転記）
B57: リスク項目 | D57: リスク項目詳細 | M57: 対策審議 | N57: 有無程度 | O57: 対策 | P57: 具体策
B62: 受注・業務着手時段階で想定されるリスクの確認・対応結果
B63: リスク項目 | D63: リスク項目詳細 | M63: 対策審議 | N63: 有無程度 | O63: 対策 | P63: 具体策
B64: 1.確認記録の不備 | D64: 案件形成時に認識していた要求事項と契約時の要求事項に差異が発生し、当社がエビデンスを提示することが出来ず、顧客の要求に従わざるを得ない。
B67: 2.顧客要求事項の未確定による作業の手戻り | D67: 受注時でもなお、要求事項が不明確である中で業務を着手せざるを得ず、作業の手戻りが発生したり、工期を順守できなくなる。
B70: 3.作業内容不明確 | D70: 品質計画（書）策定段階でのリスク抽出が出来なかった場合、見逃したリスクが後の業務実施段階で支障をきたす。
...

Sheet 顧客所有物確認書
I1: 参考帳票（2026/1/9）
B2: 顧客所有物確認書（№ ） | H2: 作成年月日 | Q2: 目次へ戻る | R2: =HYPERLINK("#目次!A2","●") -> ●
H3: 実施責任者 | J3: =基本データ!D10 -> 東設 三郎 | Q3: フローへ戻る | R3: =HYPERLINK("#フロー!A2","●") -> ●
B4: 件名コード | E4: =基本データ!D3 -> LG*****
B5: 件 名 | E5: =基本データ!D4 -> 〇〇設計業務委託 | Q5: 改訂履歴
B6: 顧客所有物の受入時の検証 | Q6: 改訂日 | R6: 改訂内容
B7: No. | D7: 名 称 | F7: 受入日 | G7: 数量 | I7: 支給品・貸与品の区別 | K7: 数量 | L7: 外見 | Q7: 44977 | R7: 特例の場合の記載欄を設けた
K8: 確認 | L8: 確認 | Q8: 44984 | R8: 使用期間後の処分・返却欄に、未定の場合でもその経緯の記録を残すようコメントを追記し、未記載に対する注意喚起した
Q9: 45043 | R9: 2022年度内部監査指摘事項に対する対応
Q10: 46031 | R10: 全体をレビュー
B14: 顧客所有物の管理，処分・返却時の検証
B15: ・支給品の場合
C16: 使用期間中の保管方法（他の物品との識別を含む）
C19: 使用期間後の処分方法
C20: （使用期間後に顧客所有物の取扱いが未定の場合や継続的に保管する場合などに、その旨記載すること）
K21: 処分確認
D25: 処分日： | E25: ×××× 年 月 日
B27: ・貸与品の場合
C28: 使用期間中の保管方法（他の物品との識別を含む）
C31: 受入日： | E31: ×××× 年 月 日
C32: 使用期間後の返却方法
C33: （使用期間後に顧客所有物の取扱いが未定の場合や継続的に保管する場合などに、その旨記載すること）
D38: 返却前確認： | E38: 数量確認：□ 外見確認：□ 確認日：×××× 年 月 日
D39: 返却日： | E39: ×××× 年 月 日
B41: ・紛失、損傷、その他の使用に適さない状況が発生した場合 【議事録の有無： □有 □無】
C42: （顧客にその内容を報告するとともに処置方法を検討し実施する。処置の経緯は、「議事録」に記録し、主管部長の承認を得る） | I42: 主管部長 | K42: 実施責任者

Sheet 安全事前評価議事録
C2: 本部長 | E2: 安全管理 担当職 | G2: 社会基盤企画総括部長 | I2: 部長 | J2: 担当職 | K2: Ｇ Ｍ | O2: メンバー
X4: 目次へ戻る | Y4: =HYPERLINK("#目次!A2","●") -> ●
X5: フローへ戻る | Y5: =HYPERLINK("#フロー!A2","●") -> ●
B8: 安全事前評価議事録 | J8: 日 時 | X8: 改訂履歴
J9: 場 所 | X9: 改訂日 | Y9: 改訂内容
B10: 件名コード 件 名 | C10: =+基本データ!D3 -> LG***** | X10: 46031 | Y10: 新規
C11: =+基本データ!D4 -> 〇〇設計業務委託
B12: 発注者 | J12: 工 期
B14: 出席者 | C14: □ | D14: 本部長 | E14: □ | F14: 安全管理担当職 | H14: □ | I14: 社会基盤企画総括部長 | L14: □ | M14: 部長
C15: □ | D15: 担当職 | E15: □ | F15: ＧＭ | H15: □ | K15: ■：出席 □：欠席
B16: 資 料 | X16: 最新版は、BC1-001 安全事前評価実施要領を確認すること
B18: 指示事項など
C29: 安全計画書における作業内容について、関係法令を確認したか | N29: □ | O29: YES | Q29: □ | R29: NO
C30: □ | D30: 計画書修正要求なし。よって、計画書内容を承認する。
C31: □ | D31: 計画書修正要求あり。
B32: 資料修正
B35: 修正結果の 確認 | C35: 本部長 | E35: 安全管理 担当職 | G35: 社会基盤企画総括部長 | I35: 部長 | J35: 担当職 | K35: Ｇ Ｍ | O35: メンバー
B41: （注）安全管理担当職までの承認後，写しを社会基盤企画総括部に提出してください。

Sheet 計測機器使用記録
H1: 参考帳票（2026/1/9）
B2: 計測機器使用記録 | M2: 目次へ戻る | N2: =HYPERLINK("#目次!A2","●") -> ●
B3: 件名コード | D3: =基本データ!D3 -> LG***** | M3: フローへ戻る | N3: =HYPERLINK("#フロー!A2","●") -> ●
B4: 件 名 | D4: =基本データ!D4 -> 〇〇設計業務委託
B6: 使用年月日 | C6: 管理番号 | D6: 計測機器名 | E6: 点 検 の 記 録 | H6: 実施責任者 | I6: 備 考 | M6: 改訂履歴
H7: 確認 | I7: 不具合時の措置等 | M7: 改訂日 | N7: 改訂内容
E8: □ | F8: 使用前の正常作動確認 | M8: 45043 | N8: 新規制定
M9: 46031 | N9: 表現の修正、チェックボックスのプルダウン選択化、全体をレビュー
E10: □ | F10: 使用後の正常作動確認
E12: □ | F12: 使用前の正常作動確認
E14: □ | F14: 使用後の正常作動確認
E16: □ | F16: 使用前の正常作動確認
E18: □ | F18: 使用後の正常作動確認
E20: □ | F20: 使用前の正常作動確認
E22: □ | F22: 使用後の正常作動確認
E24: □ | F24: 使用前の正常作動確認
E26: □ | F26: 使用後の正常作動確認
E28: □ | F28: 使用前の正常作動確認
E30: □ | F30: 使用後の正常作動確認
E32: □ | F32: 使用前の正常作動確認
... E46: □ | F46: 使用後の正常作動確認

Sheet 計測機器校正記録
H1: 参考帳票（2026/1/9）
B2: 計測機器校正記録 | M2: 目次へ戻る | N2: =HYPERLINK("#目次!A2","●") -> ●
B3: 管理番号 | M3: フローへ戻る | N3: =HYPERLINK("#フロー!A2","●") -> ●
B4: 計測機器名 | M4: 改訂履歴
B5: 日 付 | C5: 校 正 の 結 果 | H5: 備 考 | M5: 改訂日 | N5: 改訂内容
M6: 45043 | N6: 新規制定
M7: 46031 | N7: 全体をレビュー
B18: 確認 （計測機器管理責任者） | D18: 印

Sheet 別紙２出張時持ち出し管理簿
B1: 別紙2 | AL1: 東電設計株式会社_BI1-105
AM3: 年 月 日
B4: 〇〇〇〇年度 出張時持ち出し管理簿 | AV4: 目次へ戻る | AW4: =HYPERLINK("#目次!A2","●") -> ●
C5: 本部 | I5: 部 | AV5: フローへ戻る | AW5: =HYPERLINK("#フロー!A2","●") -> ●
AV7: 改訂履歴
B8: 番号 | D8: 件名番号 | G8: 情報内容 | P8: 出張日 | V8: 出張者 | Y8: 一般原子力情報セキュリティ管理者 | AC8: 出張先 | AO8: 帰還確認 | AV8: 改訂日 | AW8: 改訂内容
P9: 出発 | S9: 帰社 | Y9: 許可日 | AA9: 許可者 | AO9: 確認日 | AR9: 確認者 | AV9: 46031 | AW9: 新規追加

Sheet 別紙３原子力情報に関する教育・実績管理表
B1: 別紙3 | R1: 東電設計株式会社_BI1-105
AE2: 情報管理責任者 | AG2: 新規者講習
AA3: 年 月 日 | AE3: ｾｷｭﾘﾃｨ管理者 | AG3: 定期講習
AE4: 情報取扱い者
B6: 〇〇〇〇年度 原子力情報に関する教育・実績管理表 | AD6: 目次へ戻る | AE6: =HYPERLINK("#目次!A2","●") -> ●
C7: 本部 | G7: 部 | AD7: フローへ戻る | AE7: =HYPERLINK("#フロー!A2","●") -> ●
AD8: 改訂履歴
B9: 教育日時 | H9: 教育種別 | L9: 講師名 | O9: 教育内容 | S9: 受講者 | Z9: 備考 | AD9: 改訂日 | AE9: 改訂内容
B10: 年 月 日 ： ～ ： | AD10: 46031 | AE10: 新規追加
B11: 年 月 日 ： ～ ：
B12: 年 月 日 ： ～ ：
B13: 年 月 日 ： ～ ：
B14: 年 月 日 ： ～ ：
B15: 年 月 日 ： ～ ：
B16: 年 月 日 ： ～ ：
B17: 年 月 日 ： ～ ：
B18: 年 月 日 ： ～ ：
B19: 年 月 日 ： ～ ：
B20: 年 月 日 ： ～ ：
B21: 年 月 日 ： ～ ：
B22: 年 月 日 ： ～ ：
... B26: 年 月 日 ： ～ ：

Sheet 委託先適合性確認票
B1: 別紙4 | J1: 東電設計株式会社_BI1-105
E2: 委 託 先 適 合 性 確 認 票
Q3: 目次へ戻る | R3: =HYPERLINK("#目次!A2","●") -> ●
C4: 所属： XX本部 | D4: YY部 ZZグループ | Q4: フローへ戻る | R4: =HYPERLINK("#フロー!A2","●") -> ●
G5: 注）委託先の適合性確認結果は、過去5年間有効とし、それを超える場合は再度適合性確認を実施する
B6: No | C6: 委託先企業名 | D6: チェック項目 | H6: 合否 | I6: 確認日 | J6: 有効期限 | K6: 確認者 (一般原子力情報セキュリティ管理者) | L6: 備考 | O6: 合格 | Q6: 改訂履歴
D7: 原子力業務情報の保持のために必要な措置に関して、遵守すべき規則を定めているか？ | E7: 原子力業務情報の取扱いを管理する体制が整っているか？ | F7: 原子力業務情報の保持のために必要な措置に関して、教育を実施しているか？ | G7: 原子力業務情報を保管するための設備、情報保持のために必要な設備を設置しているか？ | O7: 合格 (要改善) | Q7: 改訂日 | R7: 改訂内容
O8: 不合格 | Q8: 46031 | R8: 新規追加
B9: 1 | C9: XXXX工業 | D9: ルールあり | E9: 実質１名が対応となっている | F9: 当社にて教育を実施 | G9: 問題なし | H9: 合格 | I9: 2020.1.20 | J9: 2025.1.20
B10: 2 | H10: 合格 (要改善)
B11: 3
B12: 4
B13: 5
B14: 6
B15: 7
B16: 8
B17: 9
B18: 10
B19: 11
B20: 12
B21: 13
B22: 14
... B25: 17

Sheet 別紙06原子力情報取り扱い管理記録
A1: 別紙6 | I1: 東電設計株式会社_BI1-105
B3: 〇〇〇〇年度 原子力情報取り扱い管理記録
M4: 目次へ戻る | N4: =HYPERLINK("#目次!A2","●") -> ●
B5: 本部 | D5: 部 | M5: フローへ戻る | N5: =HYPERLINK("#フロー!A2","●") -> ●
M6: 改訂履歴
B7: 項目 | H7: 結果／確認日／確認者 | M7: 改訂日 | N7: 改訂内容
B8: ①情報取扱者の台帳に漏れはないか？ | H8: 【確認結果】 | I8: 【確認日】 | J8: 【確認者】 | M8: 46031 | N8: 新規追加
B9: 【状況】 | H9: 良 | I9: 44640 | J9: 東設太郎
B13: ②原子力情報はきちんと決められたところに保管されているか？ | H13: 【確認結果】 | I13: 【確認日】 | J13: 【確認者】
B14: 【状況】 | H14: 良 | I14: 44640 | J14: 東設太郎
B18: ③出張に伴う情報の持ち出し台帳はきちんと運用されているか？ | H18: 【確認結果】 | I18: 【確認日】 | J18: 【確認者】
B19: 【状況】 | H19: 良 | I19: 44640 | J19: 東設太郎
B23: ④情報セキュリティに関する教育は適切に行われているか？ | H23: 【確認結果】 | I23: 【確認日】 | J23: 【確認者】
B24: 【状況】 | H24: 良 | I24: 44640 | J24: 東設太郎
B28: ⑤委託先に対する適合性確認は適切に行わ れているか、漏れはないか？ | H28: 【確認結果】 | I28: 【確認日】 | J28: 【確認者】
B29: 【状況】 | H29: 良 | I29: 44640 | J29: 東設太郎
B33: ⑥委託先のセキュリティチェックは適宜、行われているか？ | H33: 【確認結果】 | I33: 【確認日】 | J33: 【確認者】
B34: 【状況】 | H34: ＿ | I34: 44640 | J34: 東設太郎
B38: ⑦原子力情報の電子データは適切なフォルダに格納され運用されているか？ | H38: 【確認結果】 | I38: 【確認日】 | J38: 【確認者】
B39: 【状況】 | H39: 良 | I39: 44640 | J39: 東設太郎
B45: 一般原子力情報管理責任者： | H45: 総合判定： 良
H47: 日付：
B48: 【特記事項】

Sheet 設計業務依頼票
B2: 設 計 業 務 依 頼 票 | H2: 作成年月日 | N2: 使用時は最新版を確認すること【全社受注契約業務取扱要領（BB1-001）を参照】
B3: 依頼先： | G3: 主管部： | P3: 目次へ戻る | Q3: =HYPERLINK("#目次!A2","●") -> ●
P4: フローへ戻る | Q4: =HYPERLINK("#フロー!A2","●") -> ●
C5: 本部長 | D5: 部長 | E5: ＧＭ | F5: メンバー | H5: 本部長 | I5: 部長 | J5: ＧＭ | K5: メンバー
P6: 改訂履歴
P7: 改訂日 | Q7: 改訂履歴
P8: 46031 | Q8: 新規
B9: 項 目 | D9: 内 容
B10: 件名コード | D10: =基本データ!D3 -> LG*****
B11: 件 名 | D11: =基本データ!D4 -> 〇〇設計業務委託
B13: 顧 客 名 | D13: =基本データ!D5 -> 東京電力HD
B14: 受 注 期 間 | D14: 自． | E14: =基本データ!D6 -> 45017 | G14: ～ | H14: 至． | I14: =基本データ!D7 -> 45382
B15: 依 頼 内 容
C21: 連絡窓口 | D21: 主管部 | H21: 依頼先
B22: 適用する 品質又は環境ﾏﾈｼﾞﾒﾝﾄｼｽﾃﾑ | D22: □ 主管部の QMS / EMS 手順による | H22: □ 依頼先の QMS / EMS手順 による
E23: ※ 同一本部内の業務依頼については、当該欄のチェックは不要
B24: 安全管理 | D24: 現場作業がある場合、安全管理は □主管部、 □依頼先、 が主体的に行う
B25: 受 注 分 割 | D25: 配 付 先 | G25: 件名ｺｰﾄﾞ | H25: 金 額 | J25: 備 考
B26: 配 付 先 内 訳 | D26: 主 管 部
B27: ※配付先の本部は 自本部で個別に 子件名コード を設定すること | D27: 配 付 先
D28: 配 付 先
D29: 配 付 先
E30: 合 計
D32: 経理部 | F32: 経理部 | G32: 営業本部 営業第一部 | J32: ＧＭ | K32: メンバー
B33: 受注分割内容確認
B34: 規定文書名：受注契約業務取扱要領 | K34: (BB1-001(20)-08)
C38: □ 主管部の QMS / EMS 手順による
C39: 適用 ■ 主管部の QMS / EMS 手順による
C40: 適用 ■ 主管部の / EMS 手順による
C41: 適用 ■ 主管部の QMS / 手順による
C43: □ 依頼先の QMS / EMS 手順による
C44: 適用 ■ 依頼先の QMS / EMS 手順による
C45: 適用 ■ 依頼先の / EMS 手順による
C46: 適用 ■ 依頼先の QMS / 手順による

Sheet 委託計画書（変更書）
M1: 起案 年 月 日
B2: 土木本部，ジオフロント本部＊ 委託計画書/変更書 | M2: 部 | Q2: 目次へ戻る | R2: =HYPERLINK("#目次!A2","●") -> ●
I3: 本部長 | J3: 部 長 | L3: ＧＭ | M3: 実施責任者 | Q3: フローへ戻る | R3: =HYPERLINK("#フロー!A2","●") -> ●
C4: 承認 年 月 日
B5: 件名 | C5: =+基本データ!D3 -> LG***** | J5: 安全管理 | L5: 有 ・ 無 | Q5: 項 目 | S5: 本部長 | T5: 主管 部長
D6: =+基本データ!D4 -> 〇〇設計業務委託
B7: 受注業務 | D7: 受注先 | J7: 受注額 | L7: 予 想 | M7: 契 約 | Q7: 受注額が3,000万円以上の委託 | S7: ○ | T7: ―
F8: =+基本データ!D5 -> 東京電力HD | J8: （千円）
C9: ［業務概要］ | J9: 工期 | L9: =+基本データ!D6 -> 45017
L10: =+基本データ!D7 -> 45382 | Q10: 受注額3,000万円未満 | R10: 受注業務1件当りの総委託費が1,000万円以上の委託 | S10: ○ | T10: ―
B11: 委 託 計 画 | C11: 委託内容 | G11: 委託方法 | H11: 見積依頼先 | J11: 委託額（千円） | L11: 委託理由 | M11: 推薦理由
G13: □ 競争 □ 特命 | R13: 受注業務1件当りの総委託費が1,000万円未満の委託 | S13: ― | T13: ○
C14: 1
G16: □ 競争 □ 特命 | Q16: 東京電力と簡易契約(※)を行なった受注業務において，「簡易委託受注･委託発注実行書(BB1-001-07)」により委託する場合 | S16: ― | T16: ○
C17: 2
G19: □ 競争 □ 特命 | Q19: ＊：東京電力と口答契約により100万円未満で受注した場合
C20: 3
G22: □ 競争 □ 特命
C23: 4
G25: □ 競争 □ 特命
C26: 5
G28: □ 競争 □ 特命
C29: 6 | Q29: 改訂履歴
Q30: 改訂日 | R30: 改訂内容
C31: 委託総額 | L31: 外注率（％） | Q31: 45602 | R31: ①業務品質管理要領の改訂に伴う見直し ②委託理由に直接委託の場合の理由を追加 ③全体をレビュー
C32: 参 照 欄 | E32: ［委託理由］
E33: A 補助業務 D-1 総合管理業務の一部（緊急・特殊） F-1 要員不足(一般技術者) G 子会社育成
E34: B 現場専業的業務 D-2 地元企業 F-2 要員不足（若年技術者） | Q34: 45839 | R34: 全体をレビュー
E35: C 特殊技術業務 E 技術未習(将来必要)業務
J36: 【社内での要員調整を実施したか？】
I37: □ | J37: 社内での要員調整をしたが，要員確保ができなかった．
E38: 〇直接委託の場合
E39: ①医師,弁護士,公認会計士の業務に関わる契約 ②不動産の登記,鑑定に関わる契約
E40: ③国，地方自治体，公共機関,学術機関への調査,研究などに関わる契約 ④翻訳,通訳に関わる契約
E41: ⑤厚生施設運営に関わる契約 ⑥品質・環境マネジメントシステム審査登録に関わる契約
E42: ⑦上記以外で委託成果品が得られない契約（物品類の輸送,安全警備,作業補助など）
E44: ［推薦理由］…主たる理由を一つ選んでください。
F45: a 特殊専門技術 | I45: e-1：優秀な情報，設備保有
F46: b 地域事情 | I46: e-2：当社業務に精通
F47: c 緊急業務 | I47: e-3：現地精通
...

Sheet 簡易委託受注・実行書
J1: 年 月 日
B2: 簡易委託受注 ・実行書 | H2: 実
H3: 行 | P3: 目次へ戻る | Q3: =HYPERLINK("#目次!A2","●") -> ●
B4: 作成：本部・部 | F4: 部 番 号： | H4: 承 | P4: フローへ戻る | Q4: =HYPERLINK("#フロー!A2","●") -> ●
H5: 認
C6: 担 当 者 名 | E6: 氏名： | I6: 連絡先： | P6: 改訂履歴
C7: 項 目 | E7: 内 容 | J7: 新規 | K7: 0 | P7: 改訂日 | Q7: 改訂内容
B8: 受注件名 | C8: 件名ｺｰﾄﾞ | E8: =基本データ!D3 -> LG***** | P8: 46031 | Q8: 新規
C9: 件 名 | E9: =基本データ!D4 -> 〇〇設計業務委託
C11: 顧客指示日 | E11: 年 月 日
C12: 顧 客 名 | E12: =基本データ!D5 -> 東京電力HD
E13: 指示者名：
B14: 営業本部 営業企画・総括Ｇ | C14: 業 務 概 要
C17: 金 額 | I17: 円 | L17: 受付 /
C18: 期 間 | E18: 年 月 日 | H18: ～ | I18: 年 月 日 | P18: ●受注契約業務取扱要領（BB1-001）で最新版を確認すること
C19: ※需要箇所から「完了通知書・請求書」を受領した場合は、速やかに営業本部の担当者へ送付ください。
B20: 実行内容 | C20: 人 件 費
C21: 法 定 厚 生 費
C22: 委 託 費
C23: 設 計 委 託 費
C24: 直 接 経 費
C25: 間 接 原 価
B26: 経理部 決算 | C26: 計
C27: 委 託 率
C28: 粗 利 益
C30: メ モ 欄
C46: 本書の回覧順序 | E46: 作成・承認 | G46: 受注通知 | H46: 委託請求有 | J46: 委託請求 | L46: 保管
E47: 業務実施箇所 | F47: ⇒ | G47: 営業第一部 | H47: ⇒ | J47: 経理部 委託 | K47: ⇒ | L47: 業務実施箇所
I48: Copy
B49: 規定文書名：受注契約業務取扱要領 | L49: （BB1-001(20)-07）

Sheet 委託業務仕様書の作成
B1: BO1-002 委託契約要領（第19版） 別紙3-1、3-2より
P2: 目次へ戻る | Q2: =HYPERLINK("#目次!A2","●") -> ●
P3: フローへ戻る | Q3: =HYPERLINK("#フロー!A2","●") -> ●
P5: 改訂履歴
P6: 改訂日 | Q6: 改訂内容
P7: 46031 | Q7: 新規

Sheet 委託先の情報管理
C2: 資料(3)_1 2025.7.14品質情報管理会議資料 より
T3: 目次へ戻る | U3: =HYPERLINK("#目次!A2","●") -> ●
T4: フローへ戻る | U4: =HYPERLINK("#フロー!A2","●") -> ●
T6: 改訂履歴
T7: 改訂日 | U7: 改訂内容
T8: 46031 | U8: 新規
N11: セキュリティ上信頼できる業者であることを次の(2)(3)(4)により確認しなければならない。
N20: 4.協力会社へのシステムセキュリティに関するお願い

Sheet 委託先監査に関する仕様書の記載
B2: QC1-012 「委託先に対する品質監査実施の手引書」を踏まえ、委託先監査について仕様書に追記。 一般業務（原子力関連業務以外）、原子力関連業務それぞれ下記を追記。 | E2: 目次へ戻る | F2: =HYPERLINK("#目次!A2","●") -> ●
E3: フローへ戻る | F3: =HYPERLINK("#フロー!A2","●") -> ●
E5: 改訂履歴
B6: 【⼀般業務】 当社または本業務の発注元は、受託者の⾏う品質保証活動に対し、必要に応じて⽴会い、監査を⾏い、その結果に基づいて指導、勧告を⾏う。 受託者は、これに誠意をもって対処するものとする。 なお、当社または本業務の発注元は受託者の同意を得たうえで、受託者の外注先等についても、必要に応じ⽴会い、監査を⾏う。 受託者は、その旨あらかじめ外注先等に対し周知しておくものとする。 | E6: 改訂日 | F6: 改訂内容
E7: 46031 | F7: 新規追加
B14: 【原⼦⼒関連業務】 （ 品質保証および成果品の確認記録の提出） ・受託者は、業務の実施にあたり、本業務の⽬的を完遂すべく、調査、試験、作成資料、成果品、技術的検討内容等のあらゆる⾯において品質保証のための措置を講じるものとする。 ・受託者は、業務の実施に先⽴ち、品質保証の⽅針、体制、具体的⽅法等に関する計画書を当社に提出し承認を得るとともに、これを遵守するものとする。 ・受託者は、報告書の提出に先⽴って、成果品の内容に間違いがないことを確認し、この記録を提出する。確認の内容、記録の様式については、別途協議して設定するものとする。 ・受託者は、必要に応じて、当社または本業務の発注元による品質保証活動の監査を受けるものとする。その結果に基づいて指導、勧告を⾏う。受注者は、これに誠意をもって対処するものとする。 ・なお、当社または本業務の発注元は受注者の同意を得たうえで、受注者の外注先等についても必要に応じて、⽴会い、監査を⾏うものとする。 ・受注者は、その旨あらかじめ外注先等に対し周知しておくものとする。

Sheet 原子力業務の追加要求事項
B1: 原子力業務の追加要求事項
B2: 追記１ | O2: 追記２ | AA2: 目次へ戻る | AB2: =HYPERLINK("#目次!A2","●") -> ●
B3: BI1-105 一般原子力業務に係る情報セキュリティ管理要領（第2版）より | O3: 「安全文化を醸成するための活動」「10Traits」の文言の追記 | AA3: フローへ戻る | AB3: =HYPERLINK("#フロー!A2","●") -> ●
AA5: 改訂履歴
AA6: 改訂日 | AB6: 改訂内容
AA7: 46031 | AB7: 新規
AA13: 一般原子力業務に係る 情報セキュリティ管理要領
AA14: 10. 再委託における原子力情報の運用と管理
AA15: 10.1 委託先の適合性確認
AA16: 一般原子力情報セキュリティ管理者は、委託先に原子力情報を取り扱う業務を発注す
B17: 上記についての仕様書の記載（委託Gより入手した原子力本部の記載例） | AA17: る場合、事前に、その業者が下記に示す要求事項を満たし、原子力情報を保持する能力
B18: 赤枠部分（４）が上記要領の特約条項に対応 | AA18: があることを、「別紙 4 委託先適合性確認票」にて確認する。
AA19: (1) 原子力情報の保持のために必要な措置に関し遵守すべき規則を定めていること
AA20: (2) 原子力情報の取扱いを管理する体制が整っていること
AA21: (3) 原子力情報の保持のために必要な措置に関する教育を行っていること
AA22: (4) 原子力情報を保管、保持するために必要な設備を設置していること
AA23: 10.2 委託先との契約の締結
AA24: 一般原子力情報管理責任者は、委託先と契約を締結する場合、次の要求事項を契約の
AA25: 特約条項として定める。
AA26: (1) 委託先の情報管理責任者の選任に関すること
AA27: (2) 原子力情報の取扱い、保管、廃棄等の手続きに関すること
AA28: (3) 原子力情報の管理状況の確認に関すること
AA29: (4) 原子力情報の漏えい等、異常時における対応措置に関すること
AA30: (5) 原子力情報取扱い者に対する教育に関すること
... AA38: を行う。

Sheet 生成AIに関する仕様書への記載
I3: 目次へ戻る | J3: =HYPERLINK("#目次!A2","●") -> ●
I4: フローへ戻る | J4: =HYPERLINK("#フロー!A2","●") -> ●
I6: 改訂履歴
I7: 改訂日 | J7: 改訂内容
I8: 46031 | J8: 新規
B24: ＜追加仕様書への記載内容（例）＞
C25: 〇秘密の保持に関する取扱い
D26: １． | E26: 受注者は、本業務の遂行にあたって、生成AI（ChatGPT やGemini 等を典型とする、利用者の入力内容に対しAI が文章・画像等の回答を生成し、返答するシステム）を利用してはならない。
D27: ２． | E27: やむを得ず、本業務で生成AI を利用する必要がある場合には、必ず当社にその旨を書面又は電磁的方法で通知した上、当社からの承諾を得なければならない。
D28: ３． | E28: 通知に当たっては、生成AI の提供者（設置箇所（社内・社外））、生成AI の使用目的、使用箇所、利用する生成AI の名称、入力予定の情報の概要、設置箇所が社外の場合の接続方法等を記載するものとする。
D29: ４． | E29: 受注者が、当社の承認を得て、本業務の全部又は一部を第三者に再委託する場合、受注者は当該再委託先に対し、本条に定める受注者の義務と同等の義務を課すものとし、当該義務の履行について責任を負うものとする。また、再委託先が生成AI を利用しようとする場合も、上記2.に基づき当社の承諾を得るものとし、受注者は責任を持って再委託先を監督しなければならない。

Sheet 仕様書チェック表
B1: WF選定承認書/仕様書チェック項目
F2: 目次へ戻る | G2: =HYPERLINK("#目次!A2","●") -> ●
F3: フローへ戻る | G3: =HYPERLINK("#フロー!A2","●") -> ●
A4: 該当書類 | B4: 項目 | C4: ☑ | D4: チェック内容
A5: WF/仕 | B5: 件名 | D5: 選定承認書、仕様書、設計予算書・設計書など件名表記のある箇所全てで統一されていますか | F5: 改訂履歴
A6: WF/仕 | B6: 実施期間 | D6: 支払い手続き遅延防止のため完了日は月末最終営業日を避けてください。土日祝日にかかっていないですか | F6: 改訂日 | G6: 改訂内容
A7: WF/仕 | B7: 実施期間 | D7: リードタイム（右上参照）は確保されていますか。（短い場合には委託Gに相談） | F7: 46031 | G7: 新規
A8: WF/仕 | B8: 実施期間 | D8: 仕様書、承認書など実施期間の表記がある箇所全てで統一されていますか
A9: 仕 | B9: 実施期間 | D9: 契約期間記載下に但書「ただし、請書又は契約書と異なった場合には、請書又は契約書による」はありますか
A10: WF | B10: 種別 | D10: 種別は正しいですか？（XYの場合は「自社研」、YY/R＊は「委託」）
A11: 仕 | B11: 知財情報 | D11: ノウハウ表記は仕様書全ページ（図面含む）に表記されていますか（日付は現在・過去の日（仕様書作成日推奨））
A12: 仕 | B12: 提出物 | D12: 成果品がデータの場合には保存形式(pdfやxlsxなど）、提出方法(メール添付、CD-Rなど）は明記されていますか
A13: 仕 | B13: 提出物 | D13: 「完了届・請求書」（×「完了通知書・請求書」）がある場合には「当社書式・紙」と併記されていますか
A14: 仕 | B14: 提出物 | D14: 分割払いの場合には、分割検収時の成果品並びに検収日（月末最終営業日以外）を明記していますか
A15: WF | B15: 支払条件 | D15: 分割払い時には支払条件欄が「分割」になっており、検収日や支払割合などの表記はありますか 設計予算書がある場合、分割支払い分の金額が算定できますか。
A16: 仕 | B16: 提出物 | D16: 貸与資料があり、廃棄の場合には”「委託業務提示資料廃棄証明届出書」を提出”の旨記載はありますか 返却あるいは保管の場合にはその旨記載はありますか
A17: 仕 | B17: 提出物 | D17: 「廃棄」の場合には「委託業務提示資料廃棄証明届出書」の添付がありますか
A18: WF | B18: 選定理由 | D18: 選定承認書内の「選定理由」は【第三者】がわかるように具体的に記載されていますか（WF右にある「12.選定理由」を参照） 当社で契約実績がある場合には「契約番号」の表記はされていますか
A19: WF | B19: 添付ファイル | D19: 予算300万円以上の場合には「設計書」「設計予算書」が添付されていますか（拡張子はxlsxのみ）
... A25: 仕 | B25: 秘密保持 | D25: 生成AI使用可否についての注意事項の記載はありますか（26/1月作成分から適用）

Sheet ⑤別紙５委託先品質監査チェックシート
B1: 別紙5 | F1: 東電設計株式会社_BI1-105
C2: 委託先品質監査チェックシート（一般原子力業務）
E3: 委託先会社名
E4: 記 入 者 | H4: 目次へ戻る | I4: =HYPERLINK("#目次!A2","●") -> ●
E5: 記 入 日 付 | H5: フローへ戻る | I5: =HYPERLINK("#フロー!A2","●") -> ●
H6: 改訂履歴
B7: 項 目 | D7: 回 答 | F7: 備考／指示事項 | H7: 改訂日 | I7: 改訂内容
B8: 情報セキュリティ管理 | C8: 1. セキュリティ責任者の設置及び管理手法 ・業務情報の管理責任者を定め，体系的なセキュリティ管理を実施していますか。 | H8: 46031 | I8: 新規追加
C9: 2. 情報セキュリティに関するルール・マニュアル類はありますか。
C10: 3. 機密情報の持ち出し管理 ・機密情報か保存された電子媒体・ＰＣや紙類をやむを得ず保管場所以外に持ち出す場合の管理はどのように実施していますか。 ・電子媒体は暗号化されていますか。 ・出張時の資料はどのように扱っていますか。
C11: 4. 委託先に対するセキュリティ管理 ・業務を委託する会社及び協力会社に対し，どのような方法で情報セキュリティ要求事項を提示していますか。 ・委託先会社を選定する場合，情報セキュリティ面での評価を実施していますか。
C12: 5. セキュリティ事故発生時の管理 ・機密情報漏洩事故があった場合の連絡体制・連絡網は整備されていますか。また，明文化されていますか。
C13: 6. 情報発信管理 ・メールやＦＡＸにて情報を送信する場合のルールは何ですか。
C14: 7. 情報管理機器の管理 ・パソコン・モバイル機器・補助記録媒体(USB等)の紛失・盗難を防ぐために，定期的な棚卸しを実施していますか。 ・設置機器に対しては盗難防止の対策（施錠）を実施していますか。
C15: 8. 情報セキュリティに対する教育・訓練 ・従業員及び委託先に対し，定期的に情報セキュリティに対する教育を実施していますか。
C16: 9. 物理的及び環境的セキュリティ管理 ・事務所施錠や入退室管理を行い，第三者の不正な立ち入りを制限していますか。
C17: 10. 機密情報漏洩に対する人的管理 ・業務に使用する個人ＰＣやUSBメモリの利用禁止，ソフトウェア交換ソフトの利用禁止を従業員・委託先に徹底していますか。 ・個人の情報機器（BYOD)を認めていますか。認めている場合，どのような対策を行っていますか。
C18: 11. ソフトウェアの管理 ・業務用ＰＣに対し，ソフトウェアインストール制限を行い，業務以外の不要なソフトウェアが装荷されていないか管理していますか。（違法コピーも含め）
C19: 12. ウイルス・セキュリティホール管理 ・業務用ＰＣへウイルスソフトを装荷し，パターンファイルの更新やWindowsアップデデートを適切に実施していますか。 ・電子媒体にてデータを持ち込む場合，ウイルスソフトにてデータ検疫を実施していますか。
C20: 13. 電子データ・紙書類の破棄処分管理 ・ＰＣを破棄する場合，適切な方法にてハードディスク内のデータを消去し，破棄していますか。 ・紙の機密情報書類を廃棄する場合、シュレダーや溶解処理等の適切な破棄処分を実施していますか。
C21: 14. その他 ・タブレット等（iPad，Android，スマートフォン）の情報機器の利用はありますか ・利用している場合は，セキュリティ上どのような対策を行っていますか。

Sheet 変更依頼・指示書
C2: 通知 | I2: 参考帳票（2026/1/9）
E3: GM
N4: 目次へ戻る | O4: =HYPERLINK("#目次!A2","●") -> ●
N5: フローへ戻る | O5: =HYPERLINK("#フロー!A2","●") -> ●
B8: 変 更 依 頼 ・ 指 示 書（No. ） | N8: 改訂履歴
N9: 改訂日 | O9: 改訂内容
B10: 件名コード | E10: =基本データ!D3 -> LG***** | N10: 45043 | O10: 新規制定
B11: 件 名 | E11: （委託会社には，委託件名を記載） | N11: 46031 | O11: 全体をレビュー
B12: 依頼・指示日 ：
B13: 依頼・指示先 ：
B14: 依頼・指示受付者名：
B15: 依頼・指示者名 ：
B18: 依頼・指示事項
I42: 部長 | J42: 審査者
B48: 委託先への変更に関する依頼・指示 ：部長の承認（審査者欄は斜線を引く）
B49: 依頼先への変更に関する依頼・指示 ：審査者の承認（部長欄は斜線を引く）

Sheet 支給品・貸与品確認書
I1: 参考帳票（2026/1/9）
B2: 委託先への支給品・貸与品確認書（№ ） | H2: 作成年月日 | Q2: 目次へ戻る | R2: =HYPERLINK("#目次!A2","●") -> ●
H3: 実施責任者 | J3: =基本データ!D10 -> 東設 三郎 | Q3: フローへ戻る | R3: =HYPERLINK("#フロー!A2","●") -> ●
B4: 件名コード | E4: =基本データ!D3 -> LG*****
B5: 件 名 | E5: =基本データ!D4 -> 〇〇設計業務委託 | Q5: 改訂履歴
B6: 委託先名 | Q6: 改訂日 | R6: 改訂内容
B7: 支給品・貸与品がある場合の管理 | Q7: 44977 | R7: 特例の場合の記載欄を設けた
B8: ○ 下記項目の委託仕様書への記載 □有・□無 | Q8: 44977 | R8: 「委託先名」追加
B9: ・支給（貸与）資料の名称,種別および数量 | Q9: 44984 | R9: 使用期間後の処分・返却欄に、未定の場合でもその経緯の記録を残すようコメントを追記し、未記載に対する注意喚起した
B10: ・委託先での管理方法 | Q10: 45043 | R10: 2022年度内部監査指摘事項に対する対応
B11: ・返却の要否※ | Q11: 46031 | R11: 表現の修正、チェックボックスの追加、全体をレビュー
C12: ※ | D12: 貸与品は原則として要返却とする。返却不要の場合ならびに支給品についてはその処分方法の記載を確認する。
B13: 注）無の場合には、指示書又は議事録等により、指示記録を作成し、委託先と確認する。
B14: 支給（貸与）時の検証
B15: No. | D15: 名 称 | F15: 支給日 （貸与日） | G15: 数量 | I15: 支給品・貸与品の区別 | K15: 数量 | L15: 外見
K16: 確認 | L16: 確認
B21: 支給（貸与）物の管理，処分・返却時の検証
B22: ・支給品の場合
C23: 委託先での管理方法（他の物品との識別を含む）
C25: 使用期間後の処分方法 | K25: 処分確認
C26: （使用期間後に顧客所有物の取扱いが未定の場合や継続的に保管する場合などに、その旨記載すること）
C29: 処分日： | E29: ×××× 年 月 日
B31: ・貸与品の場合
C32: 使用期間中の保管方法（他の物品との識別を含む）
C34: 受入日： | E34: ×××× 年 月 日
C35: 使用期間後の返却方法
C36: （使用期間後に顧客所有物の取扱いが未定の場合や継続的に保管する場合などに、その旨記載すること）
D39: 返却前確認： | E39: 数量確認：□ 外見確認：□ 確認日： ×××× 年 月 日
D40: 返却日： | E40: ×××× 年 月 日
B42: ・紛失、損傷、その他の使用に適さない状況が発生した場合 【議事録の有無： □有 □無】
C43: （委託先にその内容を報告するとともに処置方法を検討し実施する。処置の経緯は、「議事録」に記録し、主管部長の承認を得る。） | I43: 主管部長 | K43: 実施責任者

Sheet 借用書、備品・消耗品貸出簿
L2: 目次へ戻る | M2: =HYPERLINK("#目次!A2","●") -> ●
L3: フローへ戻る | M3: =HYPERLINK("#フロー!A2","●") -> ●
L5: 改訂履歴
L6: 改訂日 | M6: 改訂内容
L7: 46031 | M7: 新規

Sheet 委託業務提示資料廃棄証明届出書
B2: 委託業務提示資料廃棄証明届出書 | AG2: 目次へ戻る | AH2: =HYPERLINK("#目次!A1","●") -> ●
AG3: フローへ戻る | AH3: =HYPERLINK("#フロー!A2","●") -> ●
V5: **** 年** 月** 日 | AG5: 改訂履歴
AG6: 改訂日 | AH6: 改訂内容
B7: （届出先） | AG7: 45839 | AH7: 新規追加
C8: 東電設計株式会社
C9: 部 御中
N12: （届出主）
N13: 住所
N14: 会社名
N15: 氏名 | AB15: ㊞
B18: 記
B20: 【委託件名】：
B22: 【委託期間】： | I22: ****年**月**日 | P22: ～ | R22: ****年**月**日
B24: 【廃棄方法】： 裁断 溶解・焼却 電子媒体破壊 データ消去
B26: その他（ ）
B29: 本委託業務につきまして貴社より提示いただきました資料については一切、当社の責任に
B30: おいて、「 **** 年 ** 月 ** 日」をもちまして廃棄・データ削除いたしましたことを
B31: 証明いたします。
AA33: 以 上
Z35: 別紙3-4

Sheet 委託成果品検査記録
K1: 参考帳票（2026/1/9）
B2: 委託成果品検査記録（No. ） | T2: 目次へ戻る | U2: =HYPERLINK("#目次!A2","●") -> ●
B3: 件名コード | F3: =基本データ!D3 -> LG***** | T3: フローへ戻る | U3: =HYPERLINK("#フロー!A2","●") -> ●
B4: 件 名 | F4: =基本データ!D4 -> 〇〇設計業務委託
B5: 委託会社名： | T5: 改訂履歴
B6: 検査日： | F6: 年 月 日（ ） | T6: 改訂日 | U6: 改訂内容
B7: 参加者名： | T7: 44917 | U7: 「計画通り」の具体的な資料名を記載する欄を設けた
T8: 44922 | U8: 検査項目1件追加
B9: 資料名： | F9: □委託仕様書，□変更依頼・指示書，□委託成果品（案）， | T9: 45043 | U9: 2022年度内部監査指摘事項に対する対応
F10: □委託審査記録，□その他（ ） | T10: 45120 | U10: 一部文言修正（設計検査→委託成果品検査）、部長押印枠削除
C11: １．検査内容及び検査結果 | T11: 45309 | U11: 検査者名を参加者名に変更（2023年度再エネ本部内部監査指摘事項対応）
C12: 検査 対象 | D12: 検査項目 | K12: 検査結果 | M12: 指摘事項の有無 | T12: 46031 | U12: 表現の修正、チェックボックスのプルダウン選択化、全体をレビュー
C14: □ | D14: 委託会社の実施計画書通り実施されているか。 | K14: □YES | L14: □NO
C15: □ | D15: 実施項目、数量・法規、基準類は計画書通り実施されているか。 | K15: □YES | L15: □NO
D16: （計画書名： ）
C17: □ | D17: インプット条件は、計画書通り設定されているか。 | K17: □YES | L17: □NO
D18: （計画書名： ）
C19: □ | D19: 設計手順は、計画書通り実施されているか。 | K19: □YES | L19: □NO
D20: （計画書名： ）
C21: □ | D21: 設計のアウトプットは、計画書通り作成されているか。 | K21: □YES | L21: □NO | M21: □有
D22: （計画書名： ）
C23: □ | D23: 使用プログラムは、計画したものを使用しているか。 | K23: □YES | L23: □NO | M23: □無
C24: □ | D24: 変更依頼・指示内容は反映されているか。 | K24: □YES | L24: □NO
C25: □ | D25: 委託会社の審査記録はあるか。 | K25: □YES | L25: □NO
C26: □ | D26: 数量変更等があった場合には，変更後の確定数量に対して成果品検査を行っているか。 | K26: □YES | L26: □NO
C28: □ | K28: □YES | L28: □NO
C30: □ | K30: □YES | L30: □NO
C31: 注意 : | D31: 「検査項目」のうち、検査を実施する項目の左欄「検査対象」のボックス（□）を「■」とする。「■」とした「検査項目」の右欄「検査結果」には、YESあるいはNOのうち、該当するボックス（□）を「■」とする。
C34: ２．指摘事項及び対応策
C35: No. | D35: 指摘事項 | H35: 処置方法 | L35: 処置結果の確認
H36: 対応者 | J36: 期日 | L36: 確認日 | O36: 確認結果
O37: □合
O39: □否
O41: □合
O43: □否
O46: 審査者
E47: □ | F47: 以上より、委託成果品検査を合格とする。

Sheet 設計検査記録
L1: 参考帳票（2026/1/9）
B2: 設計検査記録 | T2: 目次へ戻る | U2: =HYPERLINK("#目次!A2","●") -> ●
B3: 件名コード | F3: =基本データ!D3 -> LG***** | T3: フローへ戻る | U3: =HYPERLINK("#フロー!A2","●") -> ●
B4: 件 名 | F4: =基本データ!D4 -> 〇〇設計業務委託
B5: 検査日： | F5: 年 月 日（ ） | T5: 改訂履歴
B6: 参加者名： | T6: 改訂日 | U6: 改訂内容
B7: 資料名： | F7: □仕様書，□品質計画書，□実施計画書，□設計業務依頼票， | T7: 44917 | U7: 「計画通り」の具体的な資料名を記載する欄を設けた、検査項目の順番を見直し
F8: □委託成果品検査記録，□成果品（案）， | T8: 45043 | U8: 2022年度内部監査指摘事項に対する対応
F9: □議事録，□その他（ ） | T9: 46031 | U9: 表現の修正、チェックボックスのプルダウン選択化、全体をレビュー
C10: １．検査内容及び検査結果
C11: 検査対象 | D11: 検査項目 | K11: 検査結果 | M11: 指摘事項の有無
C13: □ | D13: 実施項目、数量が計画通り実施されているか。 | K13: □YES | L13: □NO
D14: （計画書名： | J14: ）
C15: □ | D15: 法規、基準類は、計画通り適用されているか。 | K15: □YES | L15: □NO
D16: （計画書名： | J16: ）
C17: □ | D17: 設計方法・手順は、計画通り実施されているか。 | K17: □YES | L17: □NO
D18: （計画書名： | J18: ）
C19: □ | D19: インプット条件は、計画通り設定されているか。 | K19: □YES | L19: □NO
D20: （計画書名： | J20: ）
C21: □ | D21: 経験，事例との比較でアウトプットに問題はないか。 | K21: □YES | L21: □NO
D22: （事例名等： | J22: ） | M22: □有
C23: □ | D23: 別法による計算との比較でアウトプットに問題はないか。 | K23: □YES | L23: □NO
D24: （別法名等： | J24: ） | M24: □無
C25: □ | D25: 委託成果品は、検査に合格しているか。 | K25: □YES | L25: □NO
C26: □ | D26: 使用プログラムは、計画したものを使用しているか。 | K26: □YES | L26: □NO
C27: □ | D27: チェックリストで確認されているか。 | K27: □YES | L27: □NO
C28: □ | D28: インプット、アウトプットの単位に、誤りはないか。 | K28: □YES | L28: □NO
C29: □ | D29: 地図・書籍等を転載時に出所・出典が記載されているか。 | K29: □YES | L29: □NO
C30: □ | D30: 品質計画書等に記載された法規・基準類から、設計に適用されていない法規・基準類は削除されているか。 | K30: □YES | L30: □NO
C32: □ | D32: 成果品はわかりやすく，簡素に表現されているか。 | K32: □YES | L32: □NO
C33: □ | K33: □YES | L33: □NO
C35: 注意 : | D35: 「検査項目」のうち、検査を実施する項目の左欄「検査対象」のボックス（□）を「■」とする。「■」とした「検査項目」の右欄「検査結果」には、YESあるいはNOのうち、該当するボックス（□）を「■」とする。
C38: ２．指摘事項及び対応策
C39: No. | D39: 指摘事項 | G39: 処置方法 | J39: 処置結果の確認
G40: 対応者 | H40: 期日 | J40: 確認日 | L40: 確認結果
L41: □合
L43: □否 | O43: 審査者
L45: □合
L47: □否
E50: □ | F50: 以上より、設計検査を合格とする。

Sheet 工程内検査記録
L1: 参考帳票（2026/1/9）
B2: 工程内検査記録 | T2: 目次へ戻る | U2: =HYPERLINK("#目次!A2","●") -> ●
B3: 件名コード | F3: =基本データ!D3 -> LG***** | T3: フローへ戻る | U3: =HYPERLINK("#フロー!A2","●") -> ●
B4: 件 名 | F4: =基本データ!D4 -> 〇〇設計業務委託
B5: 検査日： | F5: 年 月 日（ ） | T5: 改訂履歴
B6: 参加者名： | T6: 改訂日 | U6: 改訂内容
T7: 44917 | U7: 「計画通り」の具体的な資料名を記載する欄を設けた、検査項目の順番を見直し
B8: 資料名： | F8: □仕様書，□品質計画書，□実施計画書，□委託成果品検査記録， | T8: 45043 | U8: 2022年度内部監査指摘事項に対する対応
F9: □成果品（案），□議事録，□その他（ ） | T9: 46031 | U9: 表現の修正、チェックボックスのプルダウン選択化、全体をレビュー
C10: １．検査内容及び検査結果
C11: 検査 対象 | D11: 検査項目 | K11: 検査結果 | M11: 指摘事項の有無
C13: □ | D13: 実施項目、数量が計画通り実施されているか。 | K13: □YES | L13: □NO
D14: （計画書名： | J14: ）
C15: □ | D15: 法規、基準類は、計画通り適用されているか。 | K15: □YES | L15: □NO
D16: （計画書名： | J16: ）
C17: □ | D17: 設計方法・手順は、計画通り実施されているか。 | K17: □YES | L17: □NO
D18: （計画書名： | J18: ）
C19: □ | D19: インプット条件は、計画通り設定されているか。 | K19: □YES | L19: □NO
D20: （計画書名： | J20: ）
C21: □ | D21: 経験，事例との比較でアウトプットに問題はないか。 | K21: □YES | L21: □NO
D22: （事例名等： | J22: ） | M22: □有
C23: □ | D23: 別法による計算との比較でアウトプットに問題はないか。 | K23: □YES | L23: □NO
D24: （別法名等： | J24: ） | M24: □無
C25: □ | D25: 委託成果品は、検査に合格しているか。 | K25: □YES | L25: □NO
C26: □ | D26: 使用プログラムは、計画したものを使用しているか。 | K26: □YES | L26: □NO
C27: □ | D27: チェックリストで確認されているか。 | K27: □YES | L27: □NO
C28: □ | D28: インプット、アウトプットの単位に、誤りはないか。 | K28: □YES | L28: □NO
C29: □ | D29: 地図・書籍等を転載時に出所・出典が記載されているか。 | K29: □YES | L29: □NO
C30: □ | D30: 品質計画書等に記載された法規・基準類から、設計に適用されていない法規・基準類は削除されているか。 | K30: □YES | L30: □NO
C32: □ | D32: 成果品はわかりやすく，簡素に表現されているか。 | K32: □YES | L32: □NO
C33: □ | K33: □YES | L33: □NO
C34: □ | K34: □YES | L34: □NO
C35: 注意 : | D35: 「検査項目」のうち、検査を実施する項目の左欄「検査対象」のボックス（□）を「■」とする。「■」とした「検査項目」の右欄「検査結果」には、YESあるいはNOのうち、該当するボックス（□）を「■」とする。
C38: ２．指摘事項及び対応策
C39: No. | D39: 指摘事項 | G39: 処置方法 | J39: 処置結果の確認
G40: 対応者 | H40: 期日 | J40: 確認日 | L40: 確認結果
L41: □合
L43: □否 | O43: 審査者
L45: □合
L47: □否
...

Sheet 妥当性確認記録
AG1: 参考帳票（2026/1/9）
B2: 妥当性確認記録 | AT2: 目次へ戻る | AU2: =HYPERLINK("#目次!A2","●") -> ●
B3: 件名コード | I3: =基本データ!D3 -> LG***** | AT3: フローへ戻る | AU3: =HYPERLINK("#フロー!A2","●") -> ●
B4: 件 名 | I4: =基本データ!D4 -> 〇〇設計業務委託
B5: 妥当性確認日： | I5: 年 月 日（ ） | AT5: 改訂履歴
B6: 参加者名： | AT6: 改訂日 | AU6: 改訂内容
AT7: 44964 | AU7: リスク対策の有効性他の記載項目追加（全面改訂）
B8: 資料名： | I8: □仕様書，□品質計画書，□実施計画書，□設計業務依頼票，□委託関連記録， | AT8: 45030 | AU8: 書式の修正
I9: □成果品（案），□委託成果品検査記録，□設計検査記録，□工程内検査記録， | AT9: 45043 | AU9: 2022年度内部監査指摘事項に対する対応
I10: □議事録，□その他（ ） | AT10: 46031 | AU10: 表現の修正、チェックボックスのプルダウン選択化、全体をレビュー
B11: １．顧客の意向，修正要求事項の成果品（案）への反映の確認
